[2024-06-13T23:14:07.187+0000] {local_task_job_runner.py:120} INFO - ::group::Pre task execution logs
[2024-06-13T23:14:07.346+0000] {taskinstance.py:2076} INFO - Dependencies all met for dep_context=non-requeueable deps ti=<TaskInstance: Air_pollution_data_pipeline.load_data scheduled__2024-06-07T00:00:00+00:00 [queued]>
[2024-06-13T23:14:07.372+0000] {taskinstance.py:2076} INFO - Dependencies all met for dep_context=requeueable deps ti=<TaskInstance: Air_pollution_data_pipeline.load_data scheduled__2024-06-07T00:00:00+00:00 [queued]>
[2024-06-13T23:14:07.373+0000] {taskinstance.py:2306} INFO - Starting attempt 2 of 6
[2024-06-13T23:14:07.435+0000] {taskinstance.py:2330} INFO - Executing <Task(_PythonDecoratedOperator): load_data> on 2024-06-07 00:00:00+00:00
[2024-06-13T23:14:07.454+0000] {standard_task_runner.py:63} INFO - Started process 460 to run task
[2024-06-13T23:14:07.465+0000] {standard_task_runner.py:90} INFO - Running: ['***', 'tasks', 'run', 'Air_pollution_data_pipeline', 'load_data', 'scheduled__2024-06-07T00:00:00+00:00', '--job-id', '20', '--raw', '--subdir', 'DAGS_FOLDER/main.py', '--cfg-path', '/tmp/tmp4d6b0cs2']
[2024-06-13T23:14:07.473+0000] {standard_task_runner.py:91} INFO - Job 20: Subtask load_data
[2024-06-13T23:14:07.624+0000] {task_command.py:426} INFO - Running <TaskInstance: Air_pollution_data_pipeline.load_data scheduled__2024-06-07T00:00:00+00:00 [running]> on host 1ebbf628611f
[2024-06-13T23:14:07.874+0000] {taskinstance.py:2648} INFO - Exporting env vars: AIRFLOW_CTX_DAG_OWNER='khalid' AIRFLOW_CTX_DAG_ID='Air_pollution_data_pipeline' AIRFLOW_CTX_TASK_ID='load_data' AIRFLOW_CTX_EXECUTION_DATE='2024-06-07T00:00:00+00:00' AIRFLOW_CTX_TRY_NUMBER='2' AIRFLOW_CTX_DAG_RUN_ID='scheduled__2024-06-07T00:00:00+00:00'
[2024-06-13T23:14:07.877+0000] {taskinstance.py:430} INFO - ::endgroup::
[2024-06-13T23:14:07.879+0000] {data_load.py:11} INFO - starting data extration from source
[2024-06-13T23:14:10.881+0000] {data_load.py:20} ERROR - error loading data to local drive
[2024-06-13T23:14:10.882+0000] {taskinstance.py:441} INFO - ::group::Post task execution logs
[2024-06-13T23:14:10.883+0000] {taskinstance.py:2905} ERROR - Task failed with exception
Traceback (most recent call last):
  File "/home/airflow/.local/lib/python3.10/site-packages/airflow/models/taskinstance.py", line 465, in _execute_task
    result = _execute_callable(context=context, **execute_callable_kwargs)
  File "/home/airflow/.local/lib/python3.10/site-packages/airflow/models/taskinstance.py", line 432, in _execute_callable
    return execute_callable(context=context, **execute_callable_kwargs)
  File "/home/airflow/.local/lib/python3.10/site-packages/airflow/models/baseoperator.py", line 401, in wrapper
    return func(self, *args, **kwargs)
  File "/home/airflow/.local/lib/python3.10/site-packages/airflow/decorators/base.py", line 265, in execute
    return_value = super().execute(context)
  File "/home/airflow/.local/lib/python3.10/site-packages/airflow/models/baseoperator.py", line 401, in wrapper
    return func(self, *args, **kwargs)
  File "/home/airflow/.local/lib/python3.10/site-packages/airflow/operators/python.py", line 235, in execute
    return_value = self.execute_callable()
  File "/home/airflow/.local/lib/python3.10/site-packages/airflow/operators/python.py", line 252, in execute_callable
    return self.python_callable(*self.op_args, **self.op_kwargs)
  File "/opt/airflow/dags/dataload/data_load.py", line 14, in load_data
    datadf.to_csv(f'{save_path}/emission_data.csv', index= False)
  File "/home/airflow/.local/lib/python3.10/site-packages/pandas/util/_decorators.py", line 333, in wrapper
    return func(*args, **kwargs)
  File "/home/airflow/.local/lib/python3.10/site-packages/pandas/core/generic.py", line 3967, in to_csv
    return DataFrameRenderer(formatter).to_csv(
  File "/home/airflow/.local/lib/python3.10/site-packages/pandas/io/formats/format.py", line 1014, in to_csv
    csv_formatter.save()
  File "/home/airflow/.local/lib/python3.10/site-packages/pandas/io/formats/csvs.py", line 251, in save
    with get_handle(
  File "/home/airflow/.local/lib/python3.10/site-packages/pandas/io/common.py", line 873, in get_handle
    handle = open(
PermissionError: [Errno 13] Permission denied: '/opt/airflow/save/emission_data.csv'
[2024-06-13T23:14:10.915+0000] {taskinstance.py:1206} INFO - Marking task as UP_FOR_RETRY. dag_id=Air_pollution_data_pipeline, task_id=load_data, run_id=scheduled__2024-06-07T00:00:00+00:00, execution_date=20240607T000000, start_date=20240613T231407, end_date=20240613T231410
[2024-06-13T23:14:11.272+0000] {standard_task_runner.py:110} ERROR - Failed to execute job 20 for task load_data ([Errno 13] Permission denied: '/opt/airflow/save/emission_data.csv'; 460)
[2024-06-13T23:14:11.311+0000] {local_task_job_runner.py:240} INFO - Task exited with return code 1
[2024-06-13T23:14:11.396+0000] {taskinstance.py:3503} INFO - 0 downstream tasks scheduled from follow-on schedule check
[2024-06-13T23:14:11.413+0000] {local_task_job_runner.py:222} INFO - ::endgroup::
[2024-06-14T09:54:21.592+0000] {local_task_job_runner.py:120} INFO - ::group::Pre task execution logs
[2024-06-14T09:54:22.173+0000] {taskinstance.py:2076} INFO - Dependencies all met for dep_context=non-requeueable deps ti=<TaskInstance: Air_pollution_data_pipeline.load_data scheduled__2024-06-07T00:00:00+00:00 [queued]>
[2024-06-14T09:54:22.301+0000] {taskinstance.py:2076} INFO - Dependencies all met for dep_context=requeueable deps ti=<TaskInstance: Air_pollution_data_pipeline.load_data scheduled__2024-06-07T00:00:00+00:00 [queued]>
[2024-06-14T09:54:22.318+0000] {taskinstance.py:2306} INFO - Starting attempt 2 of 6
[2024-06-14T09:54:22.605+0000] {taskinstance.py:2330} INFO - Executing <Task(_PythonDecoratedOperator): load_data> on 2024-06-07 00:00:00+00:00
[2024-06-14T09:54:22.780+0000] {standard_task_runner.py:63} INFO - Started process 351 to run task
[2024-06-14T09:54:22.875+0000] {standard_task_runner.py:90} INFO - Running: ['***', 'tasks', 'run', 'Air_pollution_data_pipeline', 'load_data', 'scheduled__2024-06-07T00:00:00+00:00', '--job-id', '25', '--raw', '--subdir', 'DAGS_FOLDER/main.py', '--cfg-path', '/tmp/tmp2dnx4g_z']
[2024-06-14T09:54:22.917+0000] {standard_task_runner.py:91} INFO - Job 25: Subtask load_data
[2024-06-14T09:54:23.901+0000] {task_command.py:426} INFO - Running <TaskInstance: Air_pollution_data_pipeline.load_data scheduled__2024-06-07T00:00:00+00:00 [running]> on host 38d417aa145d
[2024-06-14T09:54:24.416+0000] {taskinstance.py:2648} INFO - Exporting env vars: AIRFLOW_CTX_DAG_OWNER='khalid' AIRFLOW_CTX_DAG_ID='Air_pollution_data_pipeline' AIRFLOW_CTX_TASK_ID='load_data' AIRFLOW_CTX_EXECUTION_DATE='2024-06-07T00:00:00+00:00' AIRFLOW_CTX_TRY_NUMBER='2' AIRFLOW_CTX_DAG_RUN_ID='scheduled__2024-06-07T00:00:00+00:00'
[2024-06-14T09:54:24.421+0000] {taskinstance.py:430} INFO - ::endgroup::
[2024-06-14T09:54:24.423+0000] {data_load.py:11} INFO - starting data extration from source
[2024-06-14T09:54:28.979+0000] {data_load.py:20} ERROR - error loading data to local drive
[2024-06-14T09:54:28.980+0000] {taskinstance.py:441} INFO - ::group::Post task execution logs
[2024-06-14T09:54:29.031+0000] {taskinstance.py:2905} ERROR - Task failed with exception
Traceback (most recent call last):
  File "/home/airflow/.local/lib/python3.10/site-packages/airflow/models/taskinstance.py", line 465, in _execute_task
    result = _execute_callable(context=context, **execute_callable_kwargs)
  File "/home/airflow/.local/lib/python3.10/site-packages/airflow/models/taskinstance.py", line 432, in _execute_callable
    return execute_callable(context=context, **execute_callable_kwargs)
  File "/home/airflow/.local/lib/python3.10/site-packages/airflow/models/baseoperator.py", line 401, in wrapper
    return func(self, *args, **kwargs)
  File "/home/airflow/.local/lib/python3.10/site-packages/airflow/decorators/base.py", line 265, in execute
    return_value = super().execute(context)
  File "/home/airflow/.local/lib/python3.10/site-packages/airflow/models/baseoperator.py", line 401, in wrapper
    return func(self, *args, **kwargs)
  File "/home/airflow/.local/lib/python3.10/site-packages/airflow/operators/python.py", line 235, in execute
    return_value = self.execute_callable()
  File "/home/airflow/.local/lib/python3.10/site-packages/airflow/operators/python.py", line 252, in execute_callable
    return self.python_callable(*self.op_args, **self.op_kwargs)
  File "/opt/airflow/dags/dataload/data_load.py", line 14, in load_data
    datadf.to_csv(f'{save_path}/emission_data.csv', index= False)
  File "/home/airflow/.local/lib/python3.10/site-packages/pandas/util/_decorators.py", line 333, in wrapper
    return func(*args, **kwargs)
  File "/home/airflow/.local/lib/python3.10/site-packages/pandas/core/generic.py", line 3967, in to_csv
    return DataFrameRenderer(formatter).to_csv(
  File "/home/airflow/.local/lib/python3.10/site-packages/pandas/io/formats/format.py", line 1014, in to_csv
    csv_formatter.save()
  File "/home/airflow/.local/lib/python3.10/site-packages/pandas/io/formats/csvs.py", line 251, in save
    with get_handle(
  File "/home/airflow/.local/lib/python3.10/site-packages/pandas/io/common.py", line 873, in get_handle
    handle = open(
PermissionError: [Errno 13] Permission denied: '/opt/airflow/save/emission_data.csv'
[2024-06-14T09:54:29.160+0000] {taskinstance.py:1206} INFO - Marking task as UP_FOR_RETRY. dag_id=Air_pollution_data_pipeline, task_id=load_data, run_id=scheduled__2024-06-07T00:00:00+00:00, execution_date=20240607T000000, start_date=20240614T095422, end_date=20240614T095429
[2024-06-14T09:54:29.491+0000] {standard_task_runner.py:110} ERROR - Failed to execute job 25 for task load_data ([Errno 13] Permission denied: '/opt/airflow/save/emission_data.csv'; 351)
[2024-06-14T09:54:29.631+0000] {local_task_job_runner.py:240} INFO - Task exited with return code 1
[2024-06-14T09:54:30.057+0000] {taskinstance.py:3503} INFO - 0 downstream tasks scheduled from follow-on schedule check
[2024-06-14T09:54:30.220+0000] {local_task_job_runner.py:222} INFO - ::endgroup::
[2024-06-14T10:04:28.006+0000] {local_task_job_runner.py:120} INFO - ::group::Pre task execution logs
[2024-06-14T10:04:28.143+0000] {taskinstance.py:2076} INFO - Dependencies all met for dep_context=non-requeueable deps ti=<TaskInstance: Air_pollution_data_pipeline.load_data scheduled__2024-06-07T00:00:00+00:00 [queued]>
[2024-06-14T10:04:28.179+0000] {taskinstance.py:2076} INFO - Dependencies all met for dep_context=requeueable deps ti=<TaskInstance: Air_pollution_data_pipeline.load_data scheduled__2024-06-07T00:00:00+00:00 [queued]>
[2024-06-14T10:04:28.180+0000] {taskinstance.py:2306} INFO - Starting attempt 2 of 6
[2024-06-14T10:04:28.219+0000] {taskinstance.py:2330} INFO - Executing <Task(_PythonDecoratedOperator): load_data> on 2024-06-07 00:00:00+00:00
[2024-06-14T10:04:28.250+0000] {standard_task_runner.py:63} INFO - Started process 337 to run task
[2024-06-14T10:04:28.262+0000] {standard_task_runner.py:90} INFO - Running: ['***', 'tasks', 'run', 'Air_pollution_data_pipeline', 'load_data', 'scheduled__2024-06-07T00:00:00+00:00', '--job-id', '25', '--raw', '--subdir', 'DAGS_FOLDER/main.py', '--cfg-path', '/tmp/tmp89iqt2n8']
[2024-06-14T10:04:28.269+0000] {standard_task_runner.py:91} INFO - Job 25: Subtask load_data
[2024-06-14T10:04:28.464+0000] {task_command.py:426} INFO - Running <TaskInstance: Air_pollution_data_pipeline.load_data scheduled__2024-06-07T00:00:00+00:00 [running]> on host aad58c289bbe
[2024-06-14T10:04:28.778+0000] {taskinstance.py:2648} INFO - Exporting env vars: AIRFLOW_CTX_DAG_OWNER='khalid' AIRFLOW_CTX_DAG_ID='Air_pollution_data_pipeline' AIRFLOW_CTX_TASK_ID='load_data' AIRFLOW_CTX_EXECUTION_DATE='2024-06-07T00:00:00+00:00' AIRFLOW_CTX_TRY_NUMBER='2' AIRFLOW_CTX_DAG_RUN_ID='scheduled__2024-06-07T00:00:00+00:00'
[2024-06-14T10:04:28.780+0000] {taskinstance.py:430} INFO - ::endgroup::
[2024-06-14T10:04:28.783+0000] {data_load.py:11} INFO - starting data extration from source
[2024-06-14T10:04:31.277+0000] {data_load.py:20} ERROR - error loading data to local drive
[2024-06-14T10:04:31.282+0000] {taskinstance.py:441} INFO - ::group::Post task execution logs
[2024-06-14T10:04:31.283+0000] {taskinstance.py:2905} ERROR - Task failed with exception
Traceback (most recent call last):
  File "/home/airflow/.local/lib/python3.10/site-packages/airflow/models/taskinstance.py", line 465, in _execute_task
    result = _execute_callable(context=context, **execute_callable_kwargs)
  File "/home/airflow/.local/lib/python3.10/site-packages/airflow/models/taskinstance.py", line 432, in _execute_callable
    return execute_callable(context=context, **execute_callable_kwargs)
  File "/home/airflow/.local/lib/python3.10/site-packages/airflow/models/baseoperator.py", line 401, in wrapper
    return func(self, *args, **kwargs)
  File "/home/airflow/.local/lib/python3.10/site-packages/airflow/decorators/base.py", line 265, in execute
    return_value = super().execute(context)
  File "/home/airflow/.local/lib/python3.10/site-packages/airflow/models/baseoperator.py", line 401, in wrapper
    return func(self, *args, **kwargs)
  File "/home/airflow/.local/lib/python3.10/site-packages/airflow/operators/python.py", line 235, in execute
    return_value = self.execute_callable()
  File "/home/airflow/.local/lib/python3.10/site-packages/airflow/operators/python.py", line 252, in execute_callable
    return self.python_callable(*self.op_args, **self.op_kwargs)
  File "/opt/airflow/dags/dataload/data_load.py", line 14, in load_data
    datadf.to_csv(f'{save_path}/emission_data.csv', index= False)
  File "/home/airflow/.local/lib/python3.10/site-packages/pandas/util/_decorators.py", line 333, in wrapper
    return func(*args, **kwargs)
  File "/home/airflow/.local/lib/python3.10/site-packages/pandas/core/generic.py", line 3967, in to_csv
    return DataFrameRenderer(formatter).to_csv(
  File "/home/airflow/.local/lib/python3.10/site-packages/pandas/io/formats/format.py", line 1014, in to_csv
    csv_formatter.save()
  File "/home/airflow/.local/lib/python3.10/site-packages/pandas/io/formats/csvs.py", line 251, in save
    with get_handle(
  File "/home/airflow/.local/lib/python3.10/site-packages/pandas/io/common.py", line 873, in get_handle
    handle = open(
PermissionError: [Errno 13] Permission denied: '/opt/airflow/save/emission_data.csv'
[2024-06-14T10:04:31.323+0000] {taskinstance.py:1206} INFO - Marking task as UP_FOR_RETRY. dag_id=Air_pollution_data_pipeline, task_id=load_data, run_id=scheduled__2024-06-07T00:00:00+00:00, execution_date=20240607T000000, start_date=20240614T100428, end_date=20240614T100431
[2024-06-14T10:04:32.375+0000] {standard_task_runner.py:110} ERROR - Failed to execute job 25 for task load_data ([Errno 13] Permission denied: '/opt/airflow/save/emission_data.csv'; 337)
[2024-06-14T10:04:32.457+0000] {local_task_job_runner.py:240} INFO - Task exited with return code 1
[2024-06-14T10:04:32.612+0000] {taskinstance.py:3503} INFO - 0 downstream tasks scheduled from follow-on schedule check
[2024-06-14T10:04:32.635+0000] {local_task_job_runner.py:222} INFO - ::endgroup::
[2024-06-14T11:38:18.414+0000] {local_task_job_runner.py:120} INFO - ::group::Pre task execution logs
[2024-06-14T11:38:18.652+0000] {taskinstance.py:2076} INFO - Dependencies all met for dep_context=non-requeueable deps ti=<TaskInstance: Air_pollution_data_pipeline.load_data scheduled__2024-06-07T00:00:00+00:00 [queued]>
[2024-06-14T11:38:18.720+0000] {taskinstance.py:2076} INFO - Dependencies all met for dep_context=requeueable deps ti=<TaskInstance: Air_pollution_data_pipeline.load_data scheduled__2024-06-07T00:00:00+00:00 [queued]>
[2024-06-14T11:38:18.728+0000] {taskinstance.py:2306} INFO - Starting attempt 2 of 6
[2024-06-14T11:38:19.431+0000] {taskinstance.py:2330} INFO - Executing <Task(_PythonDecoratedOperator): load_data> on 2024-06-07 00:00:00+00:00
[2024-06-14T11:38:19.445+0000] {standard_task_runner.py:63} INFO - Started process 367 to run task
[2024-06-14T11:38:19.467+0000] {standard_task_runner.py:90} INFO - Running: ['***', 'tasks', 'run', 'Air_pollution_data_pipeline', 'load_data', 'scheduled__2024-06-07T00:00:00+00:00', '--job-id', '25', '--raw', '--subdir', 'DAGS_FOLDER/main.py', '--cfg-path', '/tmp/tmpfjunfjdq']
[2024-06-14T11:38:19.500+0000] {standard_task_runner.py:91} INFO - Job 25: Subtask load_data
[2024-06-14T11:38:19.997+0000] {task_command.py:426} INFO - Running <TaskInstance: Air_pollution_data_pipeline.load_data scheduled__2024-06-07T00:00:00+00:00 [running]> on host 077b299c21d5
[2024-06-14T11:38:20.634+0000] {taskinstance.py:2648} INFO - Exporting env vars: AIRFLOW_CTX_DAG_OWNER='khalid' AIRFLOW_CTX_DAG_ID='Air_pollution_data_pipeline' AIRFLOW_CTX_TASK_ID='load_data' AIRFLOW_CTX_EXECUTION_DATE='2024-06-07T00:00:00+00:00' AIRFLOW_CTX_TRY_NUMBER='2' AIRFLOW_CTX_DAG_RUN_ID='scheduled__2024-06-07T00:00:00+00:00'
[2024-06-14T11:38:20.644+0000] {taskinstance.py:430} INFO - ::endgroup::
[2024-06-14T11:38:20.652+0000] {data_load.py:11} INFO - starting data extration from source
[2024-06-14T11:38:30.871+0000] {data_load.py:20} ERROR - error loading data to local drive
[2024-06-14T11:38:30.872+0000] {taskinstance.py:441} INFO - ::group::Post task execution logs
[2024-06-14T11:38:30.873+0000] {taskinstance.py:2905} ERROR - Task failed with exception
Traceback (most recent call last):
  File "/home/airflow/.local/lib/python3.10/site-packages/airflow/models/taskinstance.py", line 465, in _execute_task
    result = _execute_callable(context=context, **execute_callable_kwargs)
  File "/home/airflow/.local/lib/python3.10/site-packages/airflow/models/taskinstance.py", line 432, in _execute_callable
    return execute_callable(context=context, **execute_callable_kwargs)
  File "/home/airflow/.local/lib/python3.10/site-packages/airflow/models/baseoperator.py", line 401, in wrapper
    return func(self, *args, **kwargs)
  File "/home/airflow/.local/lib/python3.10/site-packages/airflow/decorators/base.py", line 265, in execute
    return_value = super().execute(context)
  File "/home/airflow/.local/lib/python3.10/site-packages/airflow/models/baseoperator.py", line 401, in wrapper
    return func(self, *args, **kwargs)
  File "/home/airflow/.local/lib/python3.10/site-packages/airflow/operators/python.py", line 235, in execute
    return_value = self.execute_callable()
  File "/home/airflow/.local/lib/python3.10/site-packages/airflow/operators/python.py", line 252, in execute_callable
    return self.python_callable(*self.op_args, **self.op_kwargs)
  File "/opt/airflow/dags/dataload/data_load.py", line 14, in load_data
    datadf.to_csv(f'{save_path}/emission_data.csv', index= False)
  File "/home/airflow/.local/lib/python3.10/site-packages/pandas/util/_decorators.py", line 333, in wrapper
    return func(*args, **kwargs)
  File "/home/airflow/.local/lib/python3.10/site-packages/pandas/core/generic.py", line 3967, in to_csv
    return DataFrameRenderer(formatter).to_csv(
  File "/home/airflow/.local/lib/python3.10/site-packages/pandas/io/formats/format.py", line 1014, in to_csv
    csv_formatter.save()
  File "/home/airflow/.local/lib/python3.10/site-packages/pandas/io/formats/csvs.py", line 251, in save
    with get_handle(
  File "/home/airflow/.local/lib/python3.10/site-packages/pandas/io/common.py", line 873, in get_handle
    handle = open(
PermissionError: [Errno 13] Permission denied: '/opt/airflow/save/emission_data.csv'
[2024-06-14T11:38:30.895+0000] {taskinstance.py:1206} INFO - Marking task as UP_FOR_RETRY. dag_id=Air_pollution_data_pipeline, task_id=load_data, run_id=scheduled__2024-06-07T00:00:00+00:00, execution_date=20240607T000000, start_date=20240614T113818, end_date=20240614T113830
[2024-06-14T11:38:31.160+0000] {standard_task_runner.py:110} ERROR - Failed to execute job 25 for task load_data ([Errno 13] Permission denied: '/opt/airflow/save/emission_data.csv'; 367)
[2024-06-14T11:38:31.175+0000] {local_task_job_runner.py:240} INFO - Task exited with return code 1
[2024-06-14T11:38:31.213+0000] {taskinstance.py:3503} INFO - 0 downstream tasks scheduled from follow-on schedule check
[2024-06-14T11:38:31.217+0000] {local_task_job_runner.py:222} INFO - ::endgroup::
