[2024-06-13T23:20:31.016+0000] {local_task_job_runner.py:120} INFO - ::group::Pre task execution logs
[2024-06-13T23:20:31.069+0000] {taskinstance.py:2076} INFO - Dependencies all met for dep_context=non-requeueable deps ti=<TaskInstance: Air_pollution_data_pipeline.load_data scheduled__2024-06-10T00:00:00+00:00 [queued]>
[2024-06-13T23:20:31.084+0000] {taskinstance.py:2076} INFO - Dependencies all met for dep_context=requeueable deps ti=<TaskInstance: Air_pollution_data_pipeline.load_data scheduled__2024-06-10T00:00:00+00:00 [queued]>
[2024-06-13T23:20:31.084+0000] {taskinstance.py:2306} INFO - Starting attempt 5 of 6
[2024-06-13T23:20:31.114+0000] {taskinstance.py:2330} INFO - Executing <Task(_PythonDecoratedOperator): load_data> on 2024-06-10 00:00:00+00:00
[2024-06-13T23:20:31.123+0000] {standard_task_runner.py:63} INFO - Started process 742 to run task
[2024-06-13T23:20:31.129+0000] {standard_task_runner.py:90} INFO - Running: ['***', 'tasks', 'run', 'Air_pollution_data_pipeline', 'load_data', 'scheduled__2024-06-10T00:00:00+00:00', '--job-id', '66', '--raw', '--subdir', 'DAGS_FOLDER/main.py', '--cfg-path', '/tmp/tmpb9za9hj8']
[2024-06-13T23:20:31.132+0000] {standard_task_runner.py:91} INFO - Job 66: Subtask load_data
[2024-06-13T23:20:31.230+0000] {task_command.py:426} INFO - Running <TaskInstance: Air_pollution_data_pipeline.load_data scheduled__2024-06-10T00:00:00+00:00 [running]> on host 1ebbf628611f
[2024-06-13T23:20:31.387+0000] {taskinstance.py:2648} INFO - Exporting env vars: AIRFLOW_CTX_DAG_OWNER='khalid' AIRFLOW_CTX_DAG_ID='Air_pollution_data_pipeline' AIRFLOW_CTX_TASK_ID='load_data' AIRFLOW_CTX_EXECUTION_DATE='2024-06-10T00:00:00+00:00' AIRFLOW_CTX_TRY_NUMBER='5' AIRFLOW_CTX_DAG_RUN_ID='scheduled__2024-06-10T00:00:00+00:00'
[2024-06-13T23:20:31.389+0000] {taskinstance.py:430} INFO - ::endgroup::
[2024-06-13T23:20:31.391+0000] {data_load.py:11} INFO - starting data extration from source
[2024-06-13T23:20:33.218+0000] {data_load.py:20} ERROR - error loading data to local drive
[2024-06-13T23:20:33.218+0000] {taskinstance.py:441} INFO - ::group::Post task execution logs
[2024-06-13T23:20:33.219+0000] {taskinstance.py:2905} ERROR - Task failed with exception
Traceback (most recent call last):
  File "/home/airflow/.local/lib/python3.10/site-packages/airflow/models/taskinstance.py", line 465, in _execute_task
    result = _execute_callable(context=context, **execute_callable_kwargs)
  File "/home/airflow/.local/lib/python3.10/site-packages/airflow/models/taskinstance.py", line 432, in _execute_callable
    return execute_callable(context=context, **execute_callable_kwargs)
  File "/home/airflow/.local/lib/python3.10/site-packages/airflow/models/baseoperator.py", line 401, in wrapper
    return func(self, *args, **kwargs)
  File "/home/airflow/.local/lib/python3.10/site-packages/airflow/decorators/base.py", line 265, in execute
    return_value = super().execute(context)
  File "/home/airflow/.local/lib/python3.10/site-packages/airflow/models/baseoperator.py", line 401, in wrapper
    return func(self, *args, **kwargs)
  File "/home/airflow/.local/lib/python3.10/site-packages/airflow/operators/python.py", line 235, in execute
    return_value = self.execute_callable()
  File "/home/airflow/.local/lib/python3.10/site-packages/airflow/operators/python.py", line 252, in execute_callable
    return self.python_callable(*self.op_args, **self.op_kwargs)
  File "/opt/airflow/dags/dataload/data_load.py", line 14, in load_data
    datadf.to_csv(f'{save_path}/emission_data.csv', index= False)
  File "/home/airflow/.local/lib/python3.10/site-packages/pandas/util/_decorators.py", line 333, in wrapper
    return func(*args, **kwargs)
  File "/home/airflow/.local/lib/python3.10/site-packages/pandas/core/generic.py", line 3967, in to_csv
    return DataFrameRenderer(formatter).to_csv(
  File "/home/airflow/.local/lib/python3.10/site-packages/pandas/io/formats/format.py", line 1014, in to_csv
    csv_formatter.save()
  File "/home/airflow/.local/lib/python3.10/site-packages/pandas/io/formats/csvs.py", line 251, in save
    with get_handle(
  File "/home/airflow/.local/lib/python3.10/site-packages/pandas/io/common.py", line 873, in get_handle
    handle = open(
PermissionError: [Errno 13] Permission denied: '/opt/airflow/save/emission_data.csv'
[2024-06-13T23:20:33.237+0000] {taskinstance.py:1206} INFO - Marking task as UP_FOR_RETRY. dag_id=Air_pollution_data_pipeline, task_id=load_data, run_id=scheduled__2024-06-10T00:00:00+00:00, execution_date=20240610T000000, start_date=20240613T232031, end_date=20240613T232033
[2024-06-13T23:20:33.270+0000] {standard_task_runner.py:110} ERROR - Failed to execute job 66 for task load_data ([Errno 13] Permission denied: '/opt/airflow/save/emission_data.csv'; 742)
[2024-06-13T23:20:33.318+0000] {local_task_job_runner.py:240} INFO - Task exited with return code 1
[2024-06-13T23:20:33.369+0000] {taskinstance.py:3503} INFO - 0 downstream tasks scheduled from follow-on schedule check
[2024-06-13T23:20:33.372+0000] {local_task_job_runner.py:222} INFO - ::endgroup::
[2024-06-14T10:11:02.444+0000] {local_task_job_runner.py:120} INFO - ::group::Pre task execution logs
[2024-06-14T10:11:02.491+0000] {taskinstance.py:2076} INFO - Dependencies all met for dep_context=non-requeueable deps ti=<TaskInstance: Air_pollution_data_pipeline.load_data scheduled__2024-06-10T00:00:00+00:00 [queued]>
[2024-06-14T10:11:02.506+0000] {taskinstance.py:2076} INFO - Dependencies all met for dep_context=requeueable deps ti=<TaskInstance: Air_pollution_data_pipeline.load_data scheduled__2024-06-10T00:00:00+00:00 [queued]>
[2024-06-14T10:11:02.506+0000] {taskinstance.py:2306} INFO - Starting attempt 5 of 6
[2024-06-14T10:11:02.532+0000] {taskinstance.py:2330} INFO - Executing <Task(_PythonDecoratedOperator): load_data> on 2024-06-10 00:00:00+00:00
[2024-06-14T10:11:02.542+0000] {standard_task_runner.py:63} INFO - Started process 643 to run task
[2024-06-14T10:11:02.549+0000] {standard_task_runner.py:90} INFO - Running: ['***', 'tasks', 'run', 'Air_pollution_data_pipeline', 'load_data', 'scheduled__2024-06-10T00:00:00+00:00', '--job-id', '78', '--raw', '--subdir', 'DAGS_FOLDER/main.py', '--cfg-path', '/tmp/tmpl_9kw15f']
[2024-06-14T10:11:02.553+0000] {standard_task_runner.py:91} INFO - Job 78: Subtask load_data
[2024-06-14T10:11:02.649+0000] {task_command.py:426} INFO - Running <TaskInstance: Air_pollution_data_pipeline.load_data scheduled__2024-06-10T00:00:00+00:00 [running]> on host aad58c289bbe
[2024-06-14T10:11:02.795+0000] {taskinstance.py:2648} INFO - Exporting env vars: AIRFLOW_CTX_DAG_OWNER='khalid' AIRFLOW_CTX_DAG_ID='Air_pollution_data_pipeline' AIRFLOW_CTX_TASK_ID='load_data' AIRFLOW_CTX_EXECUTION_DATE='2024-06-10T00:00:00+00:00' AIRFLOW_CTX_TRY_NUMBER='5' AIRFLOW_CTX_DAG_RUN_ID='scheduled__2024-06-10T00:00:00+00:00'
[2024-06-14T10:11:02.797+0000] {taskinstance.py:430} INFO - ::endgroup::
[2024-06-14T10:11:02.798+0000] {data_load.py:11} INFO - starting data extration from source
[2024-06-14T10:11:04.899+0000] {data_load.py:20} ERROR - error loading data to local drive
[2024-06-14T10:11:04.900+0000] {taskinstance.py:441} INFO - ::group::Post task execution logs
[2024-06-14T10:11:04.901+0000] {taskinstance.py:2905} ERROR - Task failed with exception
Traceback (most recent call last):
  File "/home/airflow/.local/lib/python3.10/site-packages/airflow/models/taskinstance.py", line 465, in _execute_task
    result = _execute_callable(context=context, **execute_callable_kwargs)
  File "/home/airflow/.local/lib/python3.10/site-packages/airflow/models/taskinstance.py", line 432, in _execute_callable
    return execute_callable(context=context, **execute_callable_kwargs)
  File "/home/airflow/.local/lib/python3.10/site-packages/airflow/models/baseoperator.py", line 401, in wrapper
    return func(self, *args, **kwargs)
  File "/home/airflow/.local/lib/python3.10/site-packages/airflow/decorators/base.py", line 265, in execute
    return_value = super().execute(context)
  File "/home/airflow/.local/lib/python3.10/site-packages/airflow/models/baseoperator.py", line 401, in wrapper
    return func(self, *args, **kwargs)
  File "/home/airflow/.local/lib/python3.10/site-packages/airflow/operators/python.py", line 235, in execute
    return_value = self.execute_callable()
  File "/home/airflow/.local/lib/python3.10/site-packages/airflow/operators/python.py", line 252, in execute_callable
    return self.python_callable(*self.op_args, **self.op_kwargs)
  File "/opt/airflow/dags/dataload/data_load.py", line 14, in load_data
    datadf.to_csv(f'{save_path}/emission_data.csv', index= False)
  File "/home/airflow/.local/lib/python3.10/site-packages/pandas/util/_decorators.py", line 333, in wrapper
    return func(*args, **kwargs)
  File "/home/airflow/.local/lib/python3.10/site-packages/pandas/core/generic.py", line 3967, in to_csv
    return DataFrameRenderer(formatter).to_csv(
  File "/home/airflow/.local/lib/python3.10/site-packages/pandas/io/formats/format.py", line 1014, in to_csv
    csv_formatter.save()
  File "/home/airflow/.local/lib/python3.10/site-packages/pandas/io/formats/csvs.py", line 251, in save
    with get_handle(
  File "/home/airflow/.local/lib/python3.10/site-packages/pandas/io/common.py", line 873, in get_handle
    handle = open(
PermissionError: [Errno 13] Permission denied: '/opt/airflow/save/emission_data.csv'
[2024-06-14T10:11:04.919+0000] {taskinstance.py:1206} INFO - Marking task as UP_FOR_RETRY. dag_id=Air_pollution_data_pipeline, task_id=load_data, run_id=scheduled__2024-06-10T00:00:00+00:00, execution_date=20240610T000000, start_date=20240614T101102, end_date=20240614T101104
[2024-06-14T10:11:05.145+0000] {standard_task_runner.py:110} ERROR - Failed to execute job 78 for task load_data ([Errno 13] Permission denied: '/opt/airflow/save/emission_data.csv'; 643)
[2024-06-14T10:11:05.173+0000] {local_task_job_runner.py:240} INFO - Task exited with return code 1
[2024-06-14T10:11:05.223+0000] {taskinstance.py:3503} INFO - 0 downstream tasks scheduled from follow-on schedule check
[2024-06-14T10:11:05.227+0000] {local_task_job_runner.py:222} INFO - ::endgroup::
[2024-06-14T11:44:46.626+0000] {local_task_job_runner.py:120} INFO - ::group::Pre task execution logs
[2024-06-14T11:44:46.709+0000] {taskinstance.py:2076} INFO - Dependencies all met for dep_context=non-requeueable deps ti=<TaskInstance: Air_pollution_data_pipeline.load_data scheduled__2024-06-10T00:00:00+00:00 [queued]>
[2024-06-14T11:44:46.731+0000] {taskinstance.py:2076} INFO - Dependencies all met for dep_context=requeueable deps ti=<TaskInstance: Air_pollution_data_pipeline.load_data scheduled__2024-06-10T00:00:00+00:00 [queued]>
[2024-06-14T11:44:46.732+0000] {taskinstance.py:2306} INFO - Starting attempt 5 of 6
[2024-06-14T11:44:46.767+0000] {taskinstance.py:2330} INFO - Executing <Task(_PythonDecoratedOperator): load_data> on 2024-06-10 00:00:00+00:00
[2024-06-14T11:44:46.780+0000] {standard_task_runner.py:63} INFO - Started process 638 to run task
[2024-06-14T11:44:46.794+0000] {standard_task_runner.py:90} INFO - Running: ['***', 'tasks', 'run', 'Air_pollution_data_pipeline', 'load_data', 'scheduled__2024-06-10T00:00:00+00:00', '--job-id', '70', '--raw', '--subdir', 'DAGS_FOLDER/main.py', '--cfg-path', '/tmp/tmp8eztlr2q']
[2024-06-14T11:44:46.801+0000] {standard_task_runner.py:91} INFO - Job 70: Subtask load_data
[2024-06-14T11:44:46.942+0000] {task_command.py:426} INFO - Running <TaskInstance: Air_pollution_data_pipeline.load_data scheduled__2024-06-10T00:00:00+00:00 [running]> on host 077b299c21d5
[2024-06-14T11:44:47.139+0000] {taskinstance.py:2648} INFO - Exporting env vars: AIRFLOW_CTX_DAG_OWNER='khalid' AIRFLOW_CTX_DAG_ID='Air_pollution_data_pipeline' AIRFLOW_CTX_TASK_ID='load_data' AIRFLOW_CTX_EXECUTION_DATE='2024-06-10T00:00:00+00:00' AIRFLOW_CTX_TRY_NUMBER='5' AIRFLOW_CTX_DAG_RUN_ID='scheduled__2024-06-10T00:00:00+00:00'
[2024-06-14T11:44:47.142+0000] {taskinstance.py:430} INFO - ::endgroup::
[2024-06-14T11:44:47.144+0000] {data_load.py:11} INFO - starting data extration from source
[2024-06-14T11:44:49.720+0000] {data_load.py:20} ERROR - error loading data to local drive
[2024-06-14T11:44:49.721+0000] {taskinstance.py:441} INFO - ::group::Post task execution logs
[2024-06-14T11:44:49.721+0000] {taskinstance.py:2905} ERROR - Task failed with exception
Traceback (most recent call last):
  File "/home/airflow/.local/lib/python3.10/site-packages/airflow/models/taskinstance.py", line 465, in _execute_task
    result = _execute_callable(context=context, **execute_callable_kwargs)
  File "/home/airflow/.local/lib/python3.10/site-packages/airflow/models/taskinstance.py", line 432, in _execute_callable
    return execute_callable(context=context, **execute_callable_kwargs)
  File "/home/airflow/.local/lib/python3.10/site-packages/airflow/models/baseoperator.py", line 401, in wrapper
    return func(self, *args, **kwargs)
  File "/home/airflow/.local/lib/python3.10/site-packages/airflow/decorators/base.py", line 265, in execute
    return_value = super().execute(context)
  File "/home/airflow/.local/lib/python3.10/site-packages/airflow/models/baseoperator.py", line 401, in wrapper
    return func(self, *args, **kwargs)
  File "/home/airflow/.local/lib/python3.10/site-packages/airflow/operators/python.py", line 235, in execute
    return_value = self.execute_callable()
  File "/home/airflow/.local/lib/python3.10/site-packages/airflow/operators/python.py", line 252, in execute_callable
    return self.python_callable(*self.op_args, **self.op_kwargs)
  File "/opt/airflow/dags/dataload/data_load.py", line 14, in load_data
    datadf.to_csv(f'{save_path}/emission_data.csv', index= False)
  File "/home/airflow/.local/lib/python3.10/site-packages/pandas/util/_decorators.py", line 333, in wrapper
    return func(*args, **kwargs)
  File "/home/airflow/.local/lib/python3.10/site-packages/pandas/core/generic.py", line 3967, in to_csv
    return DataFrameRenderer(formatter).to_csv(
  File "/home/airflow/.local/lib/python3.10/site-packages/pandas/io/formats/format.py", line 1014, in to_csv
    csv_formatter.save()
  File "/home/airflow/.local/lib/python3.10/site-packages/pandas/io/formats/csvs.py", line 251, in save
    with get_handle(
  File "/home/airflow/.local/lib/python3.10/site-packages/pandas/io/common.py", line 873, in get_handle
    handle = open(
PermissionError: [Errno 13] Permission denied: '/opt/airflow/save/emission_data.csv'
[2024-06-14T11:44:49.742+0000] {taskinstance.py:1206} INFO - Marking task as UP_FOR_RETRY. dag_id=Air_pollution_data_pipeline, task_id=load_data, run_id=scheduled__2024-06-10T00:00:00+00:00, execution_date=20240610T000000, start_date=20240614T114446, end_date=20240614T114449
[2024-06-14T11:44:49.768+0000] {standard_task_runner.py:110} ERROR - Failed to execute job 70 for task load_data ([Errno 13] Permission denied: '/opt/airflow/save/emission_data.csv'; 638)
[2024-06-14T11:44:49.792+0000] {local_task_job_runner.py:240} INFO - Task exited with return code 1
[2024-06-14T11:44:49.853+0000] {taskinstance.py:3503} INFO - 0 downstream tasks scheduled from follow-on schedule check
[2024-06-14T11:44:49.857+0000] {local_task_job_runner.py:222} INFO - ::endgroup::
