[2024-06-19T20:09:36.420+0000] {local_task_job_runner.py:120} INFO - ::group::Pre task execution logs
[2024-06-19T20:09:36.478+0000] {taskinstance.py:2076} INFO - Dependencies all met for dep_context=non-requeueable deps ti=<TaskInstance: Air_pollution_data_pipeline.create_table scheduled__2024-06-18T00:00:00+00:00 [queued]>
[2024-06-19T20:09:36.498+0000] {taskinstance.py:2076} INFO - Dependencies all met for dep_context=requeueable deps ti=<TaskInstance: Air_pollution_data_pipeline.create_table scheduled__2024-06-18T00:00:00+00:00 [queued]>
[2024-06-19T20:09:36.499+0000] {taskinstance.py:2306} INFO - Starting attempt 3 of 6
[2024-06-19T20:09:36.526+0000] {taskinstance.py:2330} INFO - Executing <Task(_PythonDecoratedOperator): create_table> on 2024-06-18 00:00:00+00:00
[2024-06-19T20:09:36.535+0000] {standard_task_runner.py:63} INFO - Started process 543 to run task
[2024-06-19T20:09:36.546+0000] {standard_task_runner.py:90} INFO - Running: ['***', 'tasks', 'run', 'Air_pollution_data_pipeline', 'create_table', 'scheduled__2024-06-18T00:00:00+00:00', '--job-id', '52', '--raw', '--subdir', 'DAGS_FOLDER/main.py', '--cfg-path', '/tmp/tmpij9rz77q']
[2024-06-19T20:09:36.550+0000] {standard_task_runner.py:91} INFO - Job 52: Subtask create_table
[2024-06-19T20:09:36.643+0000] {task_command.py:426} INFO - Running <TaskInstance: Air_pollution_data_pipeline.create_table scheduled__2024-06-18T00:00:00+00:00 [running]> on host 0bfb368fa6be
[2024-06-19T20:09:36.765+0000] {taskinstance.py:2648} INFO - Exporting env vars: AIRFLOW_CTX_DAG_OWNER='khalid' AIRFLOW_CTX_DAG_ID='Air_pollution_data_pipeline' AIRFLOW_CTX_TASK_ID='create_table' AIRFLOW_CTX_EXECUTION_DATE='2024-06-18T00:00:00+00:00' AIRFLOW_CTX_TRY_NUMBER='3' AIRFLOW_CTX_DAG_RUN_ID='scheduled__2024-06-18T00:00:00+00:00'
[2024-06-19T20:09:36.767+0000] {taskinstance.py:430} INFO - ::endgroup::
[2024-06-19T20:09:36.768+0000] {create_table.py:71} INFO - creating table
[2024-06-19T20:09:36.770+0000] {baseoperator.py:400} WARNING - SQLExecuteQueryOperator.execute cannot be called outside TaskInstance!
[2024-06-19T20:09:36.771+0000] {sql.py:276} INFO - Executing: 
        CREATE TABLE IF NOT EXISTS emission (
            `Entity` VARCHAR(100),
            `Code` VARCHAR(100),
            `Year` INT,
            `Nitrogen_oxide_NOx` FLOAT, 
            `Sulphur_dioxide_SO_emissions` FLOAT, 
            `Carbon_monoxide_CO_emissions` FLOAT, 
            `Organic_carbon_OC_emissions` FLOAT, 
            `Non_methane_volatile_organic_compounds_NMVOC_emissions` FLOAT, 
            `Black_carbon_BC_emissions` FLOAT,
            `Ammonia_NH_emissions` FLOAT
        );

[2024-06-19T20:09:36.783+0000] {create_table.py:82} ERROR - Error creating table
Traceback (most recent call last):
  File "/opt/airflow/dags/database/create_table.py", line 77, in create_table
    create_table_task.execute(context=None)  # Execute the task
  File "/home/airflow/.local/lib/python3.10/site-packages/airflow/models/baseoperator.py", line 401, in wrapper
    return func(self, *args, **kwargs)
  File "/home/airflow/.local/lib/python3.10/site-packages/airflow/providers/common/sql/operators/sql.py", line 277, in execute
    hook = self.get_db_hook()
  File "/home/airflow/.local/lib/python3.10/site-packages/airflow/providers/common/sql/operators/sql.py", line 188, in get_db_hook
    return self._hook
  File "/usr/local/lib/python3.10/functools.py", line 981, in __get__
    val = self.func(instance)
  File "/home/airflow/.local/lib/python3.10/site-packages/airflow/providers/common/sql/operators/sql.py", line 150, in _hook
    conn = BaseHook.get_connection(conn_id)
  File "/home/airflow/.local/lib/python3.10/site-packages/airflow/hooks/base.py", line 83, in get_connection
    conn = Connection.get_connection_from_secrets(conn_id)
  File "/home/airflow/.local/lib/python3.10/site-packages/airflow/models/connection.py", line 519, in get_connection_from_secrets
    raise AirflowNotFoundException(f"The conn_id `{conn_id}` isn't defined")
airflow.exceptions.AirflowNotFoundException: The conn_id `postgres_localhost` isn't defined
[2024-06-19T20:09:36.786+0000] {taskinstance.py:441} INFO - ::group::Post task execution logs
[2024-06-19T20:09:36.797+0000] {taskinstance.py:2905} ERROR - Task failed with exception
Traceback (most recent call last):
  File "/home/airflow/.local/lib/python3.10/site-packages/airflow/models/taskinstance.py", line 465, in _execute_task
    result = _execute_callable(context=context, **execute_callable_kwargs)
  File "/home/airflow/.local/lib/python3.10/site-packages/airflow/models/taskinstance.py", line 432, in _execute_callable
    return execute_callable(context=context, **execute_callable_kwargs)
  File "/home/airflow/.local/lib/python3.10/site-packages/airflow/models/baseoperator.py", line 401, in wrapper
    return func(self, *args, **kwargs)
  File "/home/airflow/.local/lib/python3.10/site-packages/airflow/decorators/base.py", line 265, in execute
    return_value = super().execute(context)
  File "/home/airflow/.local/lib/python3.10/site-packages/airflow/models/baseoperator.py", line 401, in wrapper
    return func(self, *args, **kwargs)
  File "/home/airflow/.local/lib/python3.10/site-packages/airflow/operators/python.py", line 235, in execute
    return_value = self.execute_callable()
  File "/home/airflow/.local/lib/python3.10/site-packages/airflow/operators/python.py", line 252, in execute_callable
    return self.python_callable(*self.op_args, **self.op_kwargs)
  File "/opt/airflow/dags/database/create_table.py", line 77, in create_table
    create_table_task.execute(context=None)  # Execute the task
  File "/home/airflow/.local/lib/python3.10/site-packages/airflow/models/baseoperator.py", line 401, in wrapper
    return func(self, *args, **kwargs)
  File "/home/airflow/.local/lib/python3.10/site-packages/airflow/providers/common/sql/operators/sql.py", line 277, in execute
    hook = self.get_db_hook()
  File "/home/airflow/.local/lib/python3.10/site-packages/airflow/providers/common/sql/operators/sql.py", line 188, in get_db_hook
    return self._hook
  File "/usr/local/lib/python3.10/functools.py", line 981, in __get__
    val = self.func(instance)
  File "/home/airflow/.local/lib/python3.10/site-packages/airflow/providers/common/sql/operators/sql.py", line 150, in _hook
    conn = BaseHook.get_connection(conn_id)
  File "/home/airflow/.local/lib/python3.10/site-packages/airflow/hooks/base.py", line 83, in get_connection
    conn = Connection.get_connection_from_secrets(conn_id)
  File "/home/airflow/.local/lib/python3.10/site-packages/airflow/models/connection.py", line 519, in get_connection_from_secrets
    raise AirflowNotFoundException(f"The conn_id `{conn_id}` isn't defined")
airflow.exceptions.AirflowNotFoundException: The conn_id `postgres_localhost` isn't defined
[2024-06-19T20:09:36.802+0000] {taskinstance.py:1206} INFO - Marking task as UP_FOR_RETRY. dag_id=Air_pollution_data_pipeline, task_id=create_table, run_id=scheduled__2024-06-18T00:00:00+00:00, execution_date=20240618T000000, start_date=20240619T200936, end_date=20240619T200936
[2024-06-19T20:09:36.821+0000] {standard_task_runner.py:110} ERROR - Failed to execute job 52 for task create_table (The conn_id `postgres_localhost` isn't defined; 543)
[2024-06-19T20:09:36.840+0000] {local_task_job_runner.py:240} INFO - Task exited with return code 1
[2024-06-19T20:09:36.876+0000] {taskinstance.py:3503} INFO - 0 downstream tasks scheduled from follow-on schedule check
[2024-06-19T20:09:36.880+0000] {local_task_job_runner.py:222} INFO - ::endgroup::
