[2024-06-14T09:53:52.471+0000] {local_task_job_runner.py:120} INFO - ::group::Pre task execution logs
[2024-06-14T09:53:52.531+0000] {taskinstance.py:2076} INFO - Dependencies all met for dep_context=non-requeueable deps ti=<TaskInstance: Air_pollution_data_pipeline.load_data manual__2024-06-14T09:51:10+00:00 [queued]>
[2024-06-14T09:53:52.547+0000] {taskinstance.py:2076} INFO - Dependencies all met for dep_context=requeueable deps ti=<TaskInstance: Air_pollution_data_pipeline.load_data manual__2024-06-14T09:51:10+00:00 [queued]>
[2024-06-14T09:53:52.547+0000] {taskinstance.py:2306} INFO - Starting attempt 2 of 6
[2024-06-14T09:53:52.573+0000] {taskinstance.py:2330} INFO - Executing <Task(_PythonDecoratedOperator): load_data> on 2024-06-14 09:51:10+00:00
[2024-06-14T09:53:52.582+0000] {standard_task_runner.py:63} INFO - Started process 305 to run task
[2024-06-14T09:53:52.589+0000] {standard_task_runner.py:90} INFO - Running: ['***', 'tasks', 'run', 'Air_pollution_data_pipeline', 'load_data', 'manual__2024-06-14T09:51:10+00:00', '--job-id', '18', '--raw', '--subdir', 'DAGS_FOLDER/main.py', '--cfg-path', '/tmp/tmpvm3kkoz0']
[2024-06-14T09:53:52.595+0000] {standard_task_runner.py:91} INFO - Job 18: Subtask load_data
[2024-06-14T09:53:52.817+0000] {task_command.py:426} INFO - Running <TaskInstance: Air_pollution_data_pipeline.load_data manual__2024-06-14T09:51:10+00:00 [running]> on host 38d417aa145d
[2024-06-14T09:53:53.664+0000] {taskinstance.py:2648} INFO - Exporting env vars: AIRFLOW_CTX_DAG_OWNER='khalid' AIRFLOW_CTX_DAG_ID='Air_pollution_data_pipeline' AIRFLOW_CTX_TASK_ID='load_data' AIRFLOW_CTX_EXECUTION_DATE='2024-06-14T09:51:10+00:00' AIRFLOW_CTX_TRY_NUMBER='2' AIRFLOW_CTX_DAG_RUN_ID='manual__2024-06-14T09:51:10+00:00'
[2024-06-14T09:53:53.680+0000] {taskinstance.py:430} INFO - ::endgroup::
[2024-06-14T09:53:53.685+0000] {data_load.py:11} INFO - starting data extration from source
[2024-06-14T09:53:57.495+0000] {data_load.py:20} ERROR - error loading data to local drive
[2024-06-14T09:53:57.500+0000] {taskinstance.py:441} INFO - ::group::Post task execution logs
[2024-06-14T09:53:57.502+0000] {taskinstance.py:2905} ERROR - Task failed with exception
Traceback (most recent call last):
  File "/home/airflow/.local/lib/python3.10/site-packages/airflow/models/taskinstance.py", line 465, in _execute_task
    result = _execute_callable(context=context, **execute_callable_kwargs)
  File "/home/airflow/.local/lib/python3.10/site-packages/airflow/models/taskinstance.py", line 432, in _execute_callable
    return execute_callable(context=context, **execute_callable_kwargs)
  File "/home/airflow/.local/lib/python3.10/site-packages/airflow/models/baseoperator.py", line 401, in wrapper
    return func(self, *args, **kwargs)
  File "/home/airflow/.local/lib/python3.10/site-packages/airflow/decorators/base.py", line 265, in execute
    return_value = super().execute(context)
  File "/home/airflow/.local/lib/python3.10/site-packages/airflow/models/baseoperator.py", line 401, in wrapper
    return func(self, *args, **kwargs)
  File "/home/airflow/.local/lib/python3.10/site-packages/airflow/operators/python.py", line 235, in execute
    return_value = self.execute_callable()
  File "/home/airflow/.local/lib/python3.10/site-packages/airflow/operators/python.py", line 252, in execute_callable
    return self.python_callable(*self.op_args, **self.op_kwargs)
  File "/opt/airflow/dags/dataload/data_load.py", line 14, in load_data
    datadf.to_csv(f'{save_path}/emission_data.csv', index= False)
  File "/home/airflow/.local/lib/python3.10/site-packages/pandas/util/_decorators.py", line 333, in wrapper
    return func(*args, **kwargs)
  File "/home/airflow/.local/lib/python3.10/site-packages/pandas/core/generic.py", line 3967, in to_csv
    return DataFrameRenderer(formatter).to_csv(
  File "/home/airflow/.local/lib/python3.10/site-packages/pandas/io/formats/format.py", line 1014, in to_csv
    csv_formatter.save()
  File "/home/airflow/.local/lib/python3.10/site-packages/pandas/io/formats/csvs.py", line 251, in save
    with get_handle(
  File "/home/airflow/.local/lib/python3.10/site-packages/pandas/io/common.py", line 873, in get_handle
    handle = open(
PermissionError: [Errno 13] Permission denied: '/opt/airflow/save/emission_data.csv'
[2024-06-14T09:53:57.642+0000] {taskinstance.py:1206} INFO - Marking task as UP_FOR_RETRY. dag_id=Air_pollution_data_pipeline, task_id=load_data, run_id=manual__2024-06-14T09:51:10+00:00, execution_date=20240614T095110, start_date=20240614T095352, end_date=20240614T095357
[2024-06-14T09:53:59.350+0000] {standard_task_runner.py:110} ERROR - Failed to execute job 18 for task load_data ([Errno 13] Permission denied: '/opt/airflow/save/emission_data.csv'; 305)
[2024-06-14T09:53:59.574+0000] {local_task_job_runner.py:240} INFO - Task exited with return code 1
[2024-06-14T09:53:59.739+0000] {local_task_job_runner.py:222} INFO - ::endgroup::
