[2024-06-13T23:18:18.399+0000] {local_task_job_runner.py:120} INFO - ::group::Pre task execution logs
[2024-06-13T23:18:18.457+0000] {taskinstance.py:2076} INFO - Dependencies all met for dep_context=non-requeueable deps ti=<TaskInstance: Air_pollution_data_pipeline.load_data manual__2024-06-13T23:10:50+00:00 [queued]>
[2024-06-13T23:18:18.473+0000] {taskinstance.py:2076} INFO - Dependencies all met for dep_context=requeueable deps ti=<TaskInstance: Air_pollution_data_pipeline.load_data manual__2024-06-13T23:10:50+00:00 [queued]>
[2024-06-13T23:18:18.474+0000] {taskinstance.py:2306} INFO - Starting attempt 4 of 6
[2024-06-13T23:18:18.500+0000] {taskinstance.py:2330} INFO - Executing <Task(_PythonDecoratedOperator): load_data> on 2024-06-13 23:10:50+00:00
[2024-06-13T23:18:18.510+0000] {standard_task_runner.py:63} INFO - Started process 633 to run task
[2024-06-13T23:18:18.518+0000] {standard_task_runner.py:90} INFO - Running: ['***', 'tasks', 'run', 'Air_pollution_data_pipeline', 'load_data', 'manual__2024-06-13T23:10:50+00:00', '--job-id', '45', '--raw', '--subdir', 'DAGS_FOLDER/main.py', '--cfg-path', '/tmp/tmp0gkarc3b']
[2024-06-13T23:18:18.522+0000] {standard_task_runner.py:91} INFO - Job 45: Subtask load_data
[2024-06-13T23:18:18.619+0000] {task_command.py:426} INFO - Running <TaskInstance: Air_pollution_data_pipeline.load_data manual__2024-06-13T23:10:50+00:00 [running]> on host 1ebbf628611f
[2024-06-13T23:18:18.941+0000] {taskinstance.py:2648} INFO - Exporting env vars: AIRFLOW_CTX_DAG_OWNER='khalid' AIRFLOW_CTX_DAG_ID='Air_pollution_data_pipeline' AIRFLOW_CTX_TASK_ID='load_data' AIRFLOW_CTX_EXECUTION_DATE='2024-06-13T23:10:50+00:00' AIRFLOW_CTX_TRY_NUMBER='4' AIRFLOW_CTX_DAG_RUN_ID='manual__2024-06-13T23:10:50+00:00'
[2024-06-13T23:18:18.954+0000] {taskinstance.py:430} INFO - ::endgroup::
[2024-06-13T23:18:18.956+0000] {data_load.py:11} INFO - starting data extration from source
[2024-06-13T23:18:20.652+0000] {data_load.py:20} ERROR - error loading data to local drive
[2024-06-13T23:18:20.653+0000] {taskinstance.py:441} INFO - ::group::Post task execution logs
[2024-06-13T23:18:20.654+0000] {taskinstance.py:2905} ERROR - Task failed with exception
Traceback (most recent call last):
  File "/home/airflow/.local/lib/python3.10/site-packages/airflow/models/taskinstance.py", line 465, in _execute_task
    result = _execute_callable(context=context, **execute_callable_kwargs)
  File "/home/airflow/.local/lib/python3.10/site-packages/airflow/models/taskinstance.py", line 432, in _execute_callable
    return execute_callable(context=context, **execute_callable_kwargs)
  File "/home/airflow/.local/lib/python3.10/site-packages/airflow/models/baseoperator.py", line 401, in wrapper
    return func(self, *args, **kwargs)
  File "/home/airflow/.local/lib/python3.10/site-packages/airflow/decorators/base.py", line 265, in execute
    return_value = super().execute(context)
  File "/home/airflow/.local/lib/python3.10/site-packages/airflow/models/baseoperator.py", line 401, in wrapper
    return func(self, *args, **kwargs)
  File "/home/airflow/.local/lib/python3.10/site-packages/airflow/operators/python.py", line 235, in execute
    return_value = self.execute_callable()
  File "/home/airflow/.local/lib/python3.10/site-packages/airflow/operators/python.py", line 252, in execute_callable
    return self.python_callable(*self.op_args, **self.op_kwargs)
  File "/opt/airflow/dags/dataload/data_load.py", line 14, in load_data
    datadf.to_csv(f'{save_path}/emission_data.csv', index= False)
  File "/home/airflow/.local/lib/python3.10/site-packages/pandas/util/_decorators.py", line 333, in wrapper
    return func(*args, **kwargs)
  File "/home/airflow/.local/lib/python3.10/site-packages/pandas/core/generic.py", line 3967, in to_csv
    return DataFrameRenderer(formatter).to_csv(
  File "/home/airflow/.local/lib/python3.10/site-packages/pandas/io/formats/format.py", line 1014, in to_csv
    csv_formatter.save()
  File "/home/airflow/.local/lib/python3.10/site-packages/pandas/io/formats/csvs.py", line 251, in save
    with get_handle(
  File "/home/airflow/.local/lib/python3.10/site-packages/pandas/io/common.py", line 873, in get_handle
    handle = open(
PermissionError: [Errno 13] Permission denied: '/opt/airflow/save/emission_data.csv'
[2024-06-13T23:18:20.679+0000] {taskinstance.py:1206} INFO - Marking task as UP_FOR_RETRY. dag_id=Air_pollution_data_pipeline, task_id=load_data, run_id=manual__2024-06-13T23:10:50+00:00, execution_date=20240613T231050, start_date=20240613T231818, end_date=20240613T231820
[2024-06-13T23:18:20.707+0000] {standard_task_runner.py:110} ERROR - Failed to execute job 45 for task load_data ([Errno 13] Permission denied: '/opt/airflow/save/emission_data.csv'; 633)
[2024-06-13T23:18:20.758+0000] {local_task_job_runner.py:240} INFO - Task exited with return code 1
[2024-06-13T23:18:20.820+0000] {taskinstance.py:3503} INFO - 0 downstream tasks scheduled from follow-on schedule check
[2024-06-13T23:18:20.824+0000] {local_task_job_runner.py:222} INFO - ::endgroup::
