[2024-06-13T23:16:13.114+0000] {local_task_job_runner.py:120} INFO - ::group::Pre task execution logs
[2024-06-13T23:16:13.195+0000] {taskinstance.py:2076} INFO - Dependencies all met for dep_context=non-requeueable deps ti=<TaskInstance: Air_pollution_data_pipeline.load_data scheduled__2024-06-08T00:00:00+00:00 [queued]>
[2024-06-13T23:16:13.217+0000] {taskinstance.py:2076} INFO - Dependencies all met for dep_context=requeueable deps ti=<TaskInstance: Air_pollution_data_pipeline.load_data scheduled__2024-06-08T00:00:00+00:00 [queued]>
[2024-06-13T23:16:13.218+0000] {taskinstance.py:2306} INFO - Starting attempt 3 of 6
[2024-06-13T23:16:13.527+0000] {taskinstance.py:2330} INFO - Executing <Task(_PythonDecoratedOperator): load_data> on 2024-06-08 00:00:00+00:00
[2024-06-13T23:16:13.561+0000] {standard_task_runner.py:63} INFO - Started process 553 to run task
[2024-06-13T23:16:13.610+0000] {standard_task_runner.py:90} INFO - Running: ['***', 'tasks', 'run', 'Air_pollution_data_pipeline', 'load_data', 'scheduled__2024-06-08T00:00:00+00:00', '--job-id', '34', '--raw', '--subdir', 'DAGS_FOLDER/main.py', '--cfg-path', '/tmp/tmpcu859va_']
[2024-06-13T23:16:13.627+0000] {standard_task_runner.py:91} INFO - Job 34: Subtask load_data
[2024-06-13T23:16:13.865+0000] {task_command.py:426} INFO - Running <TaskInstance: Air_pollution_data_pipeline.load_data scheduled__2024-06-08T00:00:00+00:00 [running]> on host 1ebbf628611f
[2024-06-13T23:16:14.178+0000] {taskinstance.py:2648} INFO - Exporting env vars: AIRFLOW_CTX_DAG_OWNER='khalid' AIRFLOW_CTX_DAG_ID='Air_pollution_data_pipeline' AIRFLOW_CTX_TASK_ID='load_data' AIRFLOW_CTX_EXECUTION_DATE='2024-06-08T00:00:00+00:00' AIRFLOW_CTX_TRY_NUMBER='3' AIRFLOW_CTX_DAG_RUN_ID='scheduled__2024-06-08T00:00:00+00:00'
[2024-06-13T23:16:14.181+0000] {taskinstance.py:430} INFO - ::endgroup::
[2024-06-13T23:16:14.187+0000] {data_load.py:11} INFO - starting data extration from source
[2024-06-13T23:16:18.574+0000] {data_load.py:20} ERROR - error loading data to local drive
[2024-06-13T23:16:18.575+0000] {taskinstance.py:441} INFO - ::group::Post task execution logs
[2024-06-13T23:16:18.576+0000] {taskinstance.py:2905} ERROR - Task failed with exception
Traceback (most recent call last):
  File "/home/airflow/.local/lib/python3.10/site-packages/airflow/models/taskinstance.py", line 465, in _execute_task
    result = _execute_callable(context=context, **execute_callable_kwargs)
  File "/home/airflow/.local/lib/python3.10/site-packages/airflow/models/taskinstance.py", line 432, in _execute_callable
    return execute_callable(context=context, **execute_callable_kwargs)
  File "/home/airflow/.local/lib/python3.10/site-packages/airflow/models/baseoperator.py", line 401, in wrapper
    return func(self, *args, **kwargs)
  File "/home/airflow/.local/lib/python3.10/site-packages/airflow/decorators/base.py", line 265, in execute
    return_value = super().execute(context)
  File "/home/airflow/.local/lib/python3.10/site-packages/airflow/models/baseoperator.py", line 401, in wrapper
    return func(self, *args, **kwargs)
  File "/home/airflow/.local/lib/python3.10/site-packages/airflow/operators/python.py", line 235, in execute
    return_value = self.execute_callable()
  File "/home/airflow/.local/lib/python3.10/site-packages/airflow/operators/python.py", line 252, in execute_callable
    return self.python_callable(*self.op_args, **self.op_kwargs)
  File "/opt/airflow/dags/dataload/data_load.py", line 14, in load_data
    datadf.to_csv(f'{save_path}/emission_data.csv', index= False)
  File "/home/airflow/.local/lib/python3.10/site-packages/pandas/util/_decorators.py", line 333, in wrapper
    return func(*args, **kwargs)
  File "/home/airflow/.local/lib/python3.10/site-packages/pandas/core/generic.py", line 3967, in to_csv
    return DataFrameRenderer(formatter).to_csv(
  File "/home/airflow/.local/lib/python3.10/site-packages/pandas/io/formats/format.py", line 1014, in to_csv
    csv_formatter.save()
  File "/home/airflow/.local/lib/python3.10/site-packages/pandas/io/formats/csvs.py", line 251, in save
    with get_handle(
  File "/home/airflow/.local/lib/python3.10/site-packages/pandas/io/common.py", line 873, in get_handle
    handle = open(
PermissionError: [Errno 13] Permission denied: '/opt/airflow/save/emission_data.csv'
[2024-06-13T23:16:18.602+0000] {taskinstance.py:1206} INFO - Marking task as UP_FOR_RETRY. dag_id=Air_pollution_data_pipeline, task_id=load_data, run_id=scheduled__2024-06-08T00:00:00+00:00, execution_date=20240608T000000, start_date=20240613T231613, end_date=20240613T231618
[2024-06-13T23:16:18.823+0000] {standard_task_runner.py:110} ERROR - Failed to execute job 34 for task load_data ([Errno 13] Permission denied: '/opt/airflow/save/emission_data.csv'; 553)
[2024-06-13T23:16:18.878+0000] {local_task_job_runner.py:240} INFO - Task exited with return code 1
[2024-06-13T23:16:18.959+0000] {taskinstance.py:3503} INFO - 0 downstream tasks scheduled from follow-on schedule check
[2024-06-13T23:16:18.969+0000] {local_task_job_runner.py:222} INFO - ::endgroup::
[2024-06-14T09:56:44.983+0000] {local_task_job_runner.py:120} INFO - ::group::Pre task execution logs
[2024-06-14T09:56:45.214+0000] {taskinstance.py:2076} INFO - Dependencies all met for dep_context=non-requeueable deps ti=<TaskInstance: Air_pollution_data_pipeline.load_data scheduled__2024-06-08T00:00:00+00:00 [queued]>
[2024-06-14T09:56:45.257+0000] {taskinstance.py:2076} INFO - Dependencies all met for dep_context=requeueable deps ti=<TaskInstance: Air_pollution_data_pipeline.load_data scheduled__2024-06-08T00:00:00+00:00 [queued]>
[2024-06-14T09:56:45.263+0000] {taskinstance.py:2306} INFO - Starting attempt 3 of 6
[2024-06-14T09:56:46.161+0000] {taskinstance.py:2330} INFO - Executing <Task(_PythonDecoratedOperator): load_data> on 2024-06-08 00:00:00+00:00
[2024-06-14T09:56:46.181+0000] {standard_task_runner.py:63} INFO - Started process 453 to run task
[2024-06-14T09:56:46.216+0000] {standard_task_runner.py:90} INFO - Running: ['***', 'tasks', 'run', 'Air_pollution_data_pipeline', 'load_data', 'scheduled__2024-06-08T00:00:00+00:00', '--job-id', '44', '--raw', '--subdir', 'DAGS_FOLDER/main.py', '--cfg-path', '/tmp/tmp6tzedvsa']
[2024-06-14T09:56:46.231+0000] {standard_task_runner.py:91} INFO - Job 44: Subtask load_data
[2024-06-14T09:56:46.676+0000] {task_command.py:426} INFO - Running <TaskInstance: Air_pollution_data_pipeline.load_data scheduled__2024-06-08T00:00:00+00:00 [running]> on host 38d417aa145d
[2024-06-14T09:56:47.205+0000] {taskinstance.py:2648} INFO - Exporting env vars: AIRFLOW_CTX_DAG_OWNER='khalid' AIRFLOW_CTX_DAG_ID='Air_pollution_data_pipeline' AIRFLOW_CTX_TASK_ID='load_data' AIRFLOW_CTX_EXECUTION_DATE='2024-06-08T00:00:00+00:00' AIRFLOW_CTX_TRY_NUMBER='3' AIRFLOW_CTX_DAG_RUN_ID='scheduled__2024-06-08T00:00:00+00:00'
[2024-06-14T09:56:47.211+0000] {taskinstance.py:430} INFO - ::endgroup::
[2024-06-14T09:56:47.216+0000] {data_load.py:11} INFO - starting data extration from source
[2024-06-14T09:56:49.727+0000] {data_load.py:20} ERROR - error loading data to local drive
[2024-06-14T09:56:49.729+0000] {taskinstance.py:441} INFO - ::group::Post task execution logs
[2024-06-14T09:56:49.730+0000] {taskinstance.py:2905} ERROR - Task failed with exception
Traceback (most recent call last):
  File "/home/airflow/.local/lib/python3.10/site-packages/airflow/models/taskinstance.py", line 465, in _execute_task
    result = _execute_callable(context=context, **execute_callable_kwargs)
  File "/home/airflow/.local/lib/python3.10/site-packages/airflow/models/taskinstance.py", line 432, in _execute_callable
    return execute_callable(context=context, **execute_callable_kwargs)
  File "/home/airflow/.local/lib/python3.10/site-packages/airflow/models/baseoperator.py", line 401, in wrapper
    return func(self, *args, **kwargs)
  File "/home/airflow/.local/lib/python3.10/site-packages/airflow/decorators/base.py", line 265, in execute
    return_value = super().execute(context)
  File "/home/airflow/.local/lib/python3.10/site-packages/airflow/models/baseoperator.py", line 401, in wrapper
    return func(self, *args, **kwargs)
  File "/home/airflow/.local/lib/python3.10/site-packages/airflow/operators/python.py", line 235, in execute
    return_value = self.execute_callable()
  File "/home/airflow/.local/lib/python3.10/site-packages/airflow/operators/python.py", line 252, in execute_callable
    return self.python_callable(*self.op_args, **self.op_kwargs)
  File "/opt/airflow/dags/dataload/data_load.py", line 14, in load_data
    datadf.to_csv(f'{save_path}/emission_data.csv', index= False)
  File "/home/airflow/.local/lib/python3.10/site-packages/pandas/util/_decorators.py", line 333, in wrapper
    return func(*args, **kwargs)
  File "/home/airflow/.local/lib/python3.10/site-packages/pandas/core/generic.py", line 3967, in to_csv
    return DataFrameRenderer(formatter).to_csv(
  File "/home/airflow/.local/lib/python3.10/site-packages/pandas/io/formats/format.py", line 1014, in to_csv
    csv_formatter.save()
  File "/home/airflow/.local/lib/python3.10/site-packages/pandas/io/formats/csvs.py", line 251, in save
    with get_handle(
  File "/home/airflow/.local/lib/python3.10/site-packages/pandas/io/common.py", line 873, in get_handle
    handle = open(
PermissionError: [Errno 13] Permission denied: '/opt/airflow/save/emission_data.csv'
[2024-06-14T09:56:49.757+0000] {taskinstance.py:1206} INFO - Marking task as UP_FOR_RETRY. dag_id=Air_pollution_data_pipeline, task_id=load_data, run_id=scheduled__2024-06-08T00:00:00+00:00, execution_date=20240608T000000, start_date=20240614T095645, end_date=20240614T095649
[2024-06-14T09:56:49.793+0000] {standard_task_runner.py:110} ERROR - Failed to execute job 44 for task load_data ([Errno 13] Permission denied: '/opt/airflow/save/emission_data.csv'; 453)
[2024-06-14T09:56:49.826+0000] {local_task_job_runner.py:240} INFO - Task exited with return code 1
[2024-06-14T09:56:49.850+0000] {local_task_job_runner.py:222} INFO - ::endgroup::
[2024-06-14T10:06:42.904+0000] {local_task_job_runner.py:120} INFO - ::group::Pre task execution logs
[2024-06-14T10:06:43.130+0000] {taskinstance.py:2076} INFO - Dependencies all met for dep_context=non-requeueable deps ti=<TaskInstance: Air_pollution_data_pipeline.load_data scheduled__2024-06-08T00:00:00+00:00 [queued]>
[2024-06-14T10:06:43.183+0000] {taskinstance.py:2076} INFO - Dependencies all met for dep_context=requeueable deps ti=<TaskInstance: Air_pollution_data_pipeline.load_data scheduled__2024-06-08T00:00:00+00:00 [queued]>
[2024-06-14T10:06:43.184+0000] {taskinstance.py:2306} INFO - Starting attempt 3 of 6
[2024-06-14T10:06:44.712+0000] {taskinstance.py:2330} INFO - Executing <Task(_PythonDecoratedOperator): load_data> on 2024-06-08 00:00:00+00:00
[2024-06-14T10:06:44.736+0000] {standard_task_runner.py:63} INFO - Started process 448 to run task
[2024-06-14T10:06:44.748+0000] {standard_task_runner.py:90} INFO - Running: ['***', 'tasks', 'run', 'Air_pollution_data_pipeline', 'load_data', 'scheduled__2024-06-08T00:00:00+00:00', '--job-id', '43', '--raw', '--subdir', 'DAGS_FOLDER/main.py', '--cfg-path', '/tmp/tmpikdedttx']
[2024-06-14T10:06:44.757+0000] {standard_task_runner.py:91} INFO - Job 43: Subtask load_data
[2024-06-14T10:06:45.143+0000] {task_command.py:426} INFO - Running <TaskInstance: Air_pollution_data_pipeline.load_data scheduled__2024-06-08T00:00:00+00:00 [running]> on host aad58c289bbe
[2024-06-14T10:06:45.994+0000] {taskinstance.py:2648} INFO - Exporting env vars: AIRFLOW_CTX_DAG_OWNER='khalid' AIRFLOW_CTX_DAG_ID='Air_pollution_data_pipeline' AIRFLOW_CTX_TASK_ID='load_data' AIRFLOW_CTX_EXECUTION_DATE='2024-06-08T00:00:00+00:00' AIRFLOW_CTX_TRY_NUMBER='3' AIRFLOW_CTX_DAG_RUN_ID='scheduled__2024-06-08T00:00:00+00:00'
[2024-06-14T10:06:46.002+0000] {taskinstance.py:430} INFO - ::endgroup::
[2024-06-14T10:06:46.004+0000] {data_load.py:11} INFO - starting data extration from source
[2024-06-14T10:06:48.451+0000] {data_load.py:20} ERROR - error loading data to local drive
[2024-06-14T10:06:48.452+0000] {taskinstance.py:441} INFO - ::group::Post task execution logs
[2024-06-14T10:06:48.454+0000] {taskinstance.py:2905} ERROR - Task failed with exception
Traceback (most recent call last):
  File "/home/airflow/.local/lib/python3.10/site-packages/airflow/models/taskinstance.py", line 465, in _execute_task
    result = _execute_callable(context=context, **execute_callable_kwargs)
  File "/home/airflow/.local/lib/python3.10/site-packages/airflow/models/taskinstance.py", line 432, in _execute_callable
    return execute_callable(context=context, **execute_callable_kwargs)
  File "/home/airflow/.local/lib/python3.10/site-packages/airflow/models/baseoperator.py", line 401, in wrapper
    return func(self, *args, **kwargs)
  File "/home/airflow/.local/lib/python3.10/site-packages/airflow/decorators/base.py", line 265, in execute
    return_value = super().execute(context)
  File "/home/airflow/.local/lib/python3.10/site-packages/airflow/models/baseoperator.py", line 401, in wrapper
    return func(self, *args, **kwargs)
  File "/home/airflow/.local/lib/python3.10/site-packages/airflow/operators/python.py", line 235, in execute
    return_value = self.execute_callable()
  File "/home/airflow/.local/lib/python3.10/site-packages/airflow/operators/python.py", line 252, in execute_callable
    return self.python_callable(*self.op_args, **self.op_kwargs)
  File "/opt/airflow/dags/dataload/data_load.py", line 14, in load_data
    datadf.to_csv(f'{save_path}/emission_data.csv', index= False)
  File "/home/airflow/.local/lib/python3.10/site-packages/pandas/util/_decorators.py", line 333, in wrapper
    return func(*args, **kwargs)
  File "/home/airflow/.local/lib/python3.10/site-packages/pandas/core/generic.py", line 3967, in to_csv
    return DataFrameRenderer(formatter).to_csv(
  File "/home/airflow/.local/lib/python3.10/site-packages/pandas/io/formats/format.py", line 1014, in to_csv
    csv_formatter.save()
  File "/home/airflow/.local/lib/python3.10/site-packages/pandas/io/formats/csvs.py", line 251, in save
    with get_handle(
  File "/home/airflow/.local/lib/python3.10/site-packages/pandas/io/common.py", line 873, in get_handle
    handle = open(
PermissionError: [Errno 13] Permission denied: '/opt/airflow/save/emission_data.csv'
[2024-06-14T10:06:48.500+0000] {taskinstance.py:1206} INFO - Marking task as UP_FOR_RETRY. dag_id=Air_pollution_data_pipeline, task_id=load_data, run_id=scheduled__2024-06-08T00:00:00+00:00, execution_date=20240608T000000, start_date=20240614T100643, end_date=20240614T100648
[2024-06-14T10:06:48.534+0000] {standard_task_runner.py:110} ERROR - Failed to execute job 43 for task load_data ([Errno 13] Permission denied: '/opt/airflow/save/emission_data.csv'; 448)
[2024-06-14T10:06:48.613+0000] {local_task_job_runner.py:240} INFO - Task exited with return code 1
[2024-06-14T10:06:48.726+0000] {taskinstance.py:3503} INFO - 0 downstream tasks scheduled from follow-on schedule check
[2024-06-14T10:06:48.731+0000] {local_task_job_runner.py:222} INFO - ::endgroup::
[2024-06-14T11:40:34.540+0000] {local_task_job_runner.py:120} INFO - ::group::Pre task execution logs
[2024-06-14T11:40:34.677+0000] {taskinstance.py:2076} INFO - Dependencies all met for dep_context=non-requeueable deps ti=<TaskInstance: Air_pollution_data_pipeline.load_data scheduled__2024-06-08T00:00:00+00:00 [queued]>
[2024-06-14T11:40:34.715+0000] {taskinstance.py:2076} INFO - Dependencies all met for dep_context=requeueable deps ti=<TaskInstance: Air_pollution_data_pipeline.load_data scheduled__2024-06-08T00:00:00+00:00 [queued]>
[2024-06-14T11:40:34.716+0000] {taskinstance.py:2306} INFO - Starting attempt 3 of 6
[2024-06-14T11:40:34.800+0000] {taskinstance.py:2330} INFO - Executing <Task(_PythonDecoratedOperator): load_data> on 2024-06-08 00:00:00+00:00
[2024-06-14T11:40:34.815+0000] {standard_task_runner.py:63} INFO - Started process 465 to run task
[2024-06-14T11:40:34.835+0000] {standard_task_runner.py:90} INFO - Running: ['***', 'tasks', 'run', 'Air_pollution_data_pipeline', 'load_data', 'scheduled__2024-06-08T00:00:00+00:00', '--job-id', '44', '--raw', '--subdir', 'DAGS_FOLDER/main.py', '--cfg-path', '/tmp/tmpihe5j_cd']
[2024-06-14T11:40:34.847+0000] {standard_task_runner.py:91} INFO - Job 44: Subtask load_data
[2024-06-14T11:40:35.068+0000] {task_command.py:426} INFO - Running <TaskInstance: Air_pollution_data_pipeline.load_data scheduled__2024-06-08T00:00:00+00:00 [running]> on host 077b299c21d5
[2024-06-14T11:40:35.522+0000] {taskinstance.py:2648} INFO - Exporting env vars: AIRFLOW_CTX_DAG_OWNER='khalid' AIRFLOW_CTX_DAG_ID='Air_pollution_data_pipeline' AIRFLOW_CTX_TASK_ID='load_data' AIRFLOW_CTX_EXECUTION_DATE='2024-06-08T00:00:00+00:00' AIRFLOW_CTX_TRY_NUMBER='3' AIRFLOW_CTX_DAG_RUN_ID='scheduled__2024-06-08T00:00:00+00:00'
[2024-06-14T11:40:35.537+0000] {taskinstance.py:430} INFO - ::endgroup::
[2024-06-14T11:40:35.539+0000] {data_load.py:11} INFO - starting data extration from source
[2024-06-14T11:40:37.581+0000] {data_load.py:20} ERROR - error loading data to local drive
[2024-06-14T11:40:37.583+0000] {taskinstance.py:441} INFO - ::group::Post task execution logs
[2024-06-14T11:40:37.587+0000] {taskinstance.py:2905} ERROR - Task failed with exception
Traceback (most recent call last):
  File "/home/airflow/.local/lib/python3.10/site-packages/airflow/models/taskinstance.py", line 465, in _execute_task
    result = _execute_callable(context=context, **execute_callable_kwargs)
  File "/home/airflow/.local/lib/python3.10/site-packages/airflow/models/taskinstance.py", line 432, in _execute_callable
    return execute_callable(context=context, **execute_callable_kwargs)
  File "/home/airflow/.local/lib/python3.10/site-packages/airflow/models/baseoperator.py", line 401, in wrapper
    return func(self, *args, **kwargs)
  File "/home/airflow/.local/lib/python3.10/site-packages/airflow/decorators/base.py", line 265, in execute
    return_value = super().execute(context)
  File "/home/airflow/.local/lib/python3.10/site-packages/airflow/models/baseoperator.py", line 401, in wrapper
    return func(self, *args, **kwargs)
  File "/home/airflow/.local/lib/python3.10/site-packages/airflow/operators/python.py", line 235, in execute
    return_value = self.execute_callable()
  File "/home/airflow/.local/lib/python3.10/site-packages/airflow/operators/python.py", line 252, in execute_callable
    return self.python_callable(*self.op_args, **self.op_kwargs)
  File "/opt/airflow/dags/dataload/data_load.py", line 14, in load_data
    datadf.to_csv(f'{save_path}/emission_data.csv', index= False)
  File "/home/airflow/.local/lib/python3.10/site-packages/pandas/util/_decorators.py", line 333, in wrapper
    return func(*args, **kwargs)
  File "/home/airflow/.local/lib/python3.10/site-packages/pandas/core/generic.py", line 3967, in to_csv
    return DataFrameRenderer(formatter).to_csv(
  File "/home/airflow/.local/lib/python3.10/site-packages/pandas/io/formats/format.py", line 1014, in to_csv
    csv_formatter.save()
  File "/home/airflow/.local/lib/python3.10/site-packages/pandas/io/formats/csvs.py", line 251, in save
    with get_handle(
  File "/home/airflow/.local/lib/python3.10/site-packages/pandas/io/common.py", line 873, in get_handle
    handle = open(
PermissionError: [Errno 13] Permission denied: '/opt/airflow/save/emission_data.csv'
[2024-06-14T11:40:37.644+0000] {taskinstance.py:1206} INFO - Marking task as UP_FOR_RETRY. dag_id=Air_pollution_data_pipeline, task_id=load_data, run_id=scheduled__2024-06-08T00:00:00+00:00, execution_date=20240608T000000, start_date=20240614T114034, end_date=20240614T114037
[2024-06-14T11:40:38.080+0000] {standard_task_runner.py:110} ERROR - Failed to execute job 44 for task load_data ([Errno 13] Permission denied: '/opt/airflow/save/emission_data.csv'; 465)
[2024-06-14T11:40:38.105+0000] {local_task_job_runner.py:240} INFO - Task exited with return code 1
[2024-06-14T11:40:38.198+0000] {taskinstance.py:3503} INFO - 0 downstream tasks scheduled from follow-on schedule check
[2024-06-14T11:40:38.203+0000] {local_task_job_runner.py:222} INFO - ::endgroup::
