[2024-06-13T23:13:52.239+0000] {local_task_job_runner.py:120} INFO - ::group::Pre task execution logs
[2024-06-13T23:13:52.339+0000] {taskinstance.py:2076} INFO - Dependencies all met for dep_context=non-requeueable deps ti=<TaskInstance: Air_pollution_data_pipeline.load_data scheduled__2024-06-05T00:00:00+00:00 [queued]>
[2024-06-13T23:13:52.359+0000] {taskinstance.py:2076} INFO - Dependencies all met for dep_context=requeueable deps ti=<TaskInstance: Air_pollution_data_pipeline.load_data scheduled__2024-06-05T00:00:00+00:00 [queued]>
[2024-06-13T23:13:52.360+0000] {taskinstance.py:2306} INFO - Starting attempt 2 of 6
[2024-06-13T23:13:52.400+0000] {taskinstance.py:2330} INFO - Executing <Task(_PythonDecoratedOperator): load_data> on 2024-06-05 00:00:00+00:00
[2024-06-13T23:13:52.421+0000] {standard_task_runner.py:63} INFO - Started process 438 to run task
[2024-06-13T23:13:52.452+0000] {standard_task_runner.py:90} INFO - Running: ['***', 'tasks', 'run', 'Air_pollution_data_pipeline', 'load_data', 'scheduled__2024-06-05T00:00:00+00:00', '--job-id', '10', '--raw', '--subdir', 'DAGS_FOLDER/main.py', '--cfg-path', '/tmp/tmp8vb7kcb4']
[2024-06-13T23:13:52.462+0000] {standard_task_runner.py:91} INFO - Job 10: Subtask load_data
[2024-06-13T23:13:52.863+0000] {task_command.py:426} INFO - Running <TaskInstance: Air_pollution_data_pipeline.load_data scheduled__2024-06-05T00:00:00+00:00 [running]> on host 1ebbf628611f
[2024-06-13T23:13:53.483+0000] {taskinstance.py:2648} INFO - Exporting env vars: AIRFLOW_CTX_DAG_OWNER='khalid' AIRFLOW_CTX_DAG_ID='Air_pollution_data_pipeline' AIRFLOW_CTX_TASK_ID='load_data' AIRFLOW_CTX_EXECUTION_DATE='2024-06-05T00:00:00+00:00' AIRFLOW_CTX_TRY_NUMBER='2' AIRFLOW_CTX_DAG_RUN_ID='scheduled__2024-06-05T00:00:00+00:00'
[2024-06-13T23:13:53.486+0000] {taskinstance.py:430} INFO - ::endgroup::
[2024-06-13T23:13:53.487+0000] {data_load.py:11} INFO - starting data extration from source
[2024-06-13T23:14:03.864+0000] {data_load.py:20} ERROR - error loading data to local drive
[2024-06-13T23:14:03.866+0000] {taskinstance.py:441} INFO - ::group::Post task execution logs
[2024-06-13T23:14:03.867+0000] {taskinstance.py:2905} ERROR - Task failed with exception
Traceback (most recent call last):
  File "/home/airflow/.local/lib/python3.10/site-packages/airflow/models/taskinstance.py", line 465, in _execute_task
    result = _execute_callable(context=context, **execute_callable_kwargs)
  File "/home/airflow/.local/lib/python3.10/site-packages/airflow/models/taskinstance.py", line 432, in _execute_callable
    return execute_callable(context=context, **execute_callable_kwargs)
  File "/home/airflow/.local/lib/python3.10/site-packages/airflow/models/baseoperator.py", line 401, in wrapper
    return func(self, *args, **kwargs)
  File "/home/airflow/.local/lib/python3.10/site-packages/airflow/decorators/base.py", line 265, in execute
    return_value = super().execute(context)
  File "/home/airflow/.local/lib/python3.10/site-packages/airflow/models/baseoperator.py", line 401, in wrapper
    return func(self, *args, **kwargs)
  File "/home/airflow/.local/lib/python3.10/site-packages/airflow/operators/python.py", line 235, in execute
    return_value = self.execute_callable()
  File "/home/airflow/.local/lib/python3.10/site-packages/airflow/operators/python.py", line 252, in execute_callable
    return self.python_callable(*self.op_args, **self.op_kwargs)
  File "/opt/airflow/dags/dataload/data_load.py", line 14, in load_data
    datadf.to_csv(f'{save_path}/emission_data.csv', index= False)
  File "/home/airflow/.local/lib/python3.10/site-packages/pandas/util/_decorators.py", line 333, in wrapper
    return func(*args, **kwargs)
  File "/home/airflow/.local/lib/python3.10/site-packages/pandas/core/generic.py", line 3967, in to_csv
    return DataFrameRenderer(formatter).to_csv(
  File "/home/airflow/.local/lib/python3.10/site-packages/pandas/io/formats/format.py", line 1014, in to_csv
    csv_formatter.save()
  File "/home/airflow/.local/lib/python3.10/site-packages/pandas/io/formats/csvs.py", line 251, in save
    with get_handle(
  File "/home/airflow/.local/lib/python3.10/site-packages/pandas/io/common.py", line 873, in get_handle
    handle = open(
PermissionError: [Errno 13] Permission denied: '/opt/airflow/save/emission_data.csv'
[2024-06-13T23:14:03.934+0000] {taskinstance.py:1206} INFO - Marking task as UP_FOR_RETRY. dag_id=Air_pollution_data_pipeline, task_id=load_data, run_id=scheduled__2024-06-05T00:00:00+00:00, execution_date=20240605T000000, start_date=20240613T231352, end_date=20240613T231403
[2024-06-13T23:14:04.025+0000] {standard_task_runner.py:110} ERROR - Failed to execute job 10 for task load_data ([Errno 13] Permission denied: '/opt/airflow/save/emission_data.csv'; 438)
[2024-06-13T23:14:04.114+0000] {local_task_job_runner.py:240} INFO - Task exited with return code 1
[2024-06-13T23:14:04.241+0000] {taskinstance.py:3503} INFO - 0 downstream tasks scheduled from follow-on schedule check
[2024-06-13T23:14:04.263+0000] {local_task_job_runner.py:222} INFO - ::endgroup::
[2024-06-14T09:54:28.708+0000] {local_task_job_runner.py:120} INFO - ::group::Pre task execution logs
[2024-06-14T09:54:29.032+0000] {taskinstance.py:2076} INFO - Dependencies all met for dep_context=non-requeueable deps ti=<TaskInstance: Air_pollution_data_pipeline.load_data scheduled__2024-06-05T00:00:00+00:00 [queued]>
[2024-06-14T09:54:29.195+0000] {taskinstance.py:2076} INFO - Dependencies all met for dep_context=requeueable deps ti=<TaskInstance: Air_pollution_data_pipeline.load_data scheduled__2024-06-05T00:00:00+00:00 [queued]>
[2024-06-14T09:54:29.198+0000] {taskinstance.py:2306} INFO - Starting attempt 2 of 6
[2024-06-14T09:54:29.414+0000] {taskinstance.py:2330} INFO - Executing <Task(_PythonDecoratedOperator): load_data> on 2024-06-05 00:00:00+00:00
[2024-06-14T09:54:29.448+0000] {standard_task_runner.py:63} INFO - Started process 352 to run task
[2024-06-14T09:54:29.523+0000] {standard_task_runner.py:90} INFO - Running: ['***', 'tasks', 'run', 'Air_pollution_data_pipeline', 'load_data', 'scheduled__2024-06-05T00:00:00+00:00', '--job-id', '27', '--raw', '--subdir', 'DAGS_FOLDER/main.py', '--cfg-path', '/tmp/tmpe928nn3h']
[2024-06-14T09:54:29.566+0000] {standard_task_runner.py:91} INFO - Job 27: Subtask load_data
[2024-06-14T09:54:30.689+0000] {task_command.py:426} INFO - Running <TaskInstance: Air_pollution_data_pipeline.load_data scheduled__2024-06-05T00:00:00+00:00 [running]> on host 38d417aa145d
[2024-06-14T09:54:31.784+0000] {taskinstance.py:2648} INFO - Exporting env vars: AIRFLOW_CTX_DAG_OWNER='khalid' AIRFLOW_CTX_DAG_ID='Air_pollution_data_pipeline' AIRFLOW_CTX_TASK_ID='load_data' AIRFLOW_CTX_EXECUTION_DATE='2024-06-05T00:00:00+00:00' AIRFLOW_CTX_TRY_NUMBER='2' AIRFLOW_CTX_DAG_RUN_ID='scheduled__2024-06-05T00:00:00+00:00'
[2024-06-14T09:54:31.820+0000] {taskinstance.py:430} INFO - ::endgroup::
[2024-06-14T09:54:31.833+0000] {data_load.py:11} INFO - starting data extration from source
[2024-06-14T09:54:35.690+0000] {data_load.py:20} ERROR - error loading data to local drive
[2024-06-14T09:54:35.692+0000] {taskinstance.py:441} INFO - ::group::Post task execution logs
[2024-06-14T09:54:35.693+0000] {taskinstance.py:2905} ERROR - Task failed with exception
Traceback (most recent call last):
  File "/home/airflow/.local/lib/python3.10/site-packages/airflow/models/taskinstance.py", line 465, in _execute_task
    result = _execute_callable(context=context, **execute_callable_kwargs)
  File "/home/airflow/.local/lib/python3.10/site-packages/airflow/models/taskinstance.py", line 432, in _execute_callable
    return execute_callable(context=context, **execute_callable_kwargs)
  File "/home/airflow/.local/lib/python3.10/site-packages/airflow/models/baseoperator.py", line 401, in wrapper
    return func(self, *args, **kwargs)
  File "/home/airflow/.local/lib/python3.10/site-packages/airflow/decorators/base.py", line 265, in execute
    return_value = super().execute(context)
  File "/home/airflow/.local/lib/python3.10/site-packages/airflow/models/baseoperator.py", line 401, in wrapper
    return func(self, *args, **kwargs)
  File "/home/airflow/.local/lib/python3.10/site-packages/airflow/operators/python.py", line 235, in execute
    return_value = self.execute_callable()
  File "/home/airflow/.local/lib/python3.10/site-packages/airflow/operators/python.py", line 252, in execute_callable
    return self.python_callable(*self.op_args, **self.op_kwargs)
  File "/opt/airflow/dags/dataload/data_load.py", line 14, in load_data
    datadf.to_csv(f'{save_path}/emission_data.csv', index= False)
  File "/home/airflow/.local/lib/python3.10/site-packages/pandas/util/_decorators.py", line 333, in wrapper
    return func(*args, **kwargs)
  File "/home/airflow/.local/lib/python3.10/site-packages/pandas/core/generic.py", line 3967, in to_csv
    return DataFrameRenderer(formatter).to_csv(
  File "/home/airflow/.local/lib/python3.10/site-packages/pandas/io/formats/format.py", line 1014, in to_csv
    csv_formatter.save()
  File "/home/airflow/.local/lib/python3.10/site-packages/pandas/io/formats/csvs.py", line 251, in save
    with get_handle(
  File "/home/airflow/.local/lib/python3.10/site-packages/pandas/io/common.py", line 873, in get_handle
    handle = open(
PermissionError: [Errno 13] Permission denied: '/opt/airflow/save/emission_data.csv'
[2024-06-14T09:54:35.770+0000] {taskinstance.py:1206} INFO - Marking task as UP_FOR_RETRY. dag_id=Air_pollution_data_pipeline, task_id=load_data, run_id=scheduled__2024-06-05T00:00:00+00:00, execution_date=20240605T000000, start_date=20240614T095429, end_date=20240614T095435
[2024-06-14T09:54:37.832+0000] {standard_task_runner.py:110} ERROR - Failed to execute job 27 for task load_data ([Errno 13] Permission denied: '/opt/airflow/save/emission_data.csv'; 352)
[2024-06-14T09:54:37.967+0000] {local_task_job_runner.py:240} INFO - Task exited with return code 1
[2024-06-14T09:54:38.130+0000] {taskinstance.py:3503} INFO - 0 downstream tasks scheduled from follow-on schedule check
[2024-06-14T09:54:38.180+0000] {local_task_job_runner.py:222} INFO - ::endgroup::
[2024-06-14T10:04:32.905+0000] {local_task_job_runner.py:120} INFO - ::group::Pre task execution logs
[2024-06-14T10:04:33.032+0000] {taskinstance.py:2076} INFO - Dependencies all met for dep_context=non-requeueable deps ti=<TaskInstance: Air_pollution_data_pipeline.load_data scheduled__2024-06-05T00:00:00+00:00 [queued]>
[2024-06-14T10:04:33.056+0000] {taskinstance.py:2076} INFO - Dependencies all met for dep_context=requeueable deps ti=<TaskInstance: Air_pollution_data_pipeline.load_data scheduled__2024-06-05T00:00:00+00:00 [queued]>
[2024-06-14T10:04:33.057+0000] {taskinstance.py:2306} INFO - Starting attempt 2 of 6
[2024-06-14T10:04:33.110+0000] {taskinstance.py:2330} INFO - Executing <Task(_PythonDecoratedOperator): load_data> on 2024-06-05 00:00:00+00:00
[2024-06-14T10:04:33.134+0000] {standard_task_runner.py:63} INFO - Started process 358 to run task
[2024-06-14T10:04:33.160+0000] {standard_task_runner.py:90} INFO - Running: ['***', 'tasks', 'run', 'Air_pollution_data_pipeline', 'load_data', 'scheduled__2024-06-05T00:00:00+00:00', '--job-id', '29', '--raw', '--subdir', 'DAGS_FOLDER/main.py', '--cfg-path', '/tmp/tmpqhv22tqa']
[2024-06-14T10:04:33.212+0000] {standard_task_runner.py:91} INFO - Job 29: Subtask load_data
[2024-06-14T10:04:33.423+0000] {task_command.py:426} INFO - Running <TaskInstance: Air_pollution_data_pipeline.load_data scheduled__2024-06-05T00:00:00+00:00 [running]> on host aad58c289bbe
[2024-06-14T10:04:33.891+0000] {taskinstance.py:2648} INFO - Exporting env vars: AIRFLOW_CTX_DAG_OWNER='khalid' AIRFLOW_CTX_DAG_ID='Air_pollution_data_pipeline' AIRFLOW_CTX_TASK_ID='load_data' AIRFLOW_CTX_EXECUTION_DATE='2024-06-05T00:00:00+00:00' AIRFLOW_CTX_TRY_NUMBER='2' AIRFLOW_CTX_DAG_RUN_ID='scheduled__2024-06-05T00:00:00+00:00'
[2024-06-14T10:04:33.895+0000] {taskinstance.py:430} INFO - ::endgroup::
[2024-06-14T10:04:33.897+0000] {data_load.py:11} INFO - starting data extration from source
[2024-06-14T10:04:38.775+0000] {data_load.py:20} ERROR - error loading data to local drive
[2024-06-14T10:04:38.776+0000] {taskinstance.py:441} INFO - ::group::Post task execution logs
[2024-06-14T10:04:38.777+0000] {taskinstance.py:2905} ERROR - Task failed with exception
Traceback (most recent call last):
  File "/home/airflow/.local/lib/python3.10/site-packages/airflow/models/taskinstance.py", line 465, in _execute_task
    result = _execute_callable(context=context, **execute_callable_kwargs)
  File "/home/airflow/.local/lib/python3.10/site-packages/airflow/models/taskinstance.py", line 432, in _execute_callable
    return execute_callable(context=context, **execute_callable_kwargs)
  File "/home/airflow/.local/lib/python3.10/site-packages/airflow/models/baseoperator.py", line 401, in wrapper
    return func(self, *args, **kwargs)
  File "/home/airflow/.local/lib/python3.10/site-packages/airflow/decorators/base.py", line 265, in execute
    return_value = super().execute(context)
  File "/home/airflow/.local/lib/python3.10/site-packages/airflow/models/baseoperator.py", line 401, in wrapper
    return func(self, *args, **kwargs)
  File "/home/airflow/.local/lib/python3.10/site-packages/airflow/operators/python.py", line 235, in execute
    return_value = self.execute_callable()
  File "/home/airflow/.local/lib/python3.10/site-packages/airflow/operators/python.py", line 252, in execute_callable
    return self.python_callable(*self.op_args, **self.op_kwargs)
  File "/opt/airflow/dags/dataload/data_load.py", line 14, in load_data
    datadf.to_csv(f'{save_path}/emission_data.csv', index= False)
  File "/home/airflow/.local/lib/python3.10/site-packages/pandas/util/_decorators.py", line 333, in wrapper
    return func(*args, **kwargs)
  File "/home/airflow/.local/lib/python3.10/site-packages/pandas/core/generic.py", line 3967, in to_csv
    return DataFrameRenderer(formatter).to_csv(
  File "/home/airflow/.local/lib/python3.10/site-packages/pandas/io/formats/format.py", line 1014, in to_csv
    csv_formatter.save()
  File "/home/airflow/.local/lib/python3.10/site-packages/pandas/io/formats/csvs.py", line 251, in save
    with get_handle(
  File "/home/airflow/.local/lib/python3.10/site-packages/pandas/io/common.py", line 873, in get_handle
    handle = open(
PermissionError: [Errno 13] Permission denied: '/opt/airflow/save/emission_data.csv'
[2024-06-14T10:04:38.792+0000] {taskinstance.py:1206} INFO - Marking task as UP_FOR_RETRY. dag_id=Air_pollution_data_pipeline, task_id=load_data, run_id=scheduled__2024-06-05T00:00:00+00:00, execution_date=20240605T000000, start_date=20240614T100433, end_date=20240614T100438
[2024-06-14T10:04:38.813+0000] {standard_task_runner.py:110} ERROR - Failed to execute job 29 for task load_data ([Errno 13] Permission denied: '/opt/airflow/save/emission_data.csv'; 358)
[2024-06-14T10:04:38.862+0000] {local_task_job_runner.py:240} INFO - Task exited with return code 1
[2024-06-14T10:04:38.899+0000] {taskinstance.py:3503} INFO - 0 downstream tasks scheduled from follow-on schedule check
[2024-06-14T10:04:38.903+0000] {local_task_job_runner.py:222} INFO - ::endgroup::
[2024-06-14T11:38:18.654+0000] {local_task_job_runner.py:120} INFO - ::group::Pre task execution logs
[2024-06-14T11:38:18.952+0000] {taskinstance.py:2076} INFO - Dependencies all met for dep_context=non-requeueable deps ti=<TaskInstance: Air_pollution_data_pipeline.load_data scheduled__2024-06-05T00:00:00+00:00 [queued]>
[2024-06-14T11:38:18.983+0000] {taskinstance.py:2076} INFO - Dependencies all met for dep_context=requeueable deps ti=<TaskInstance: Air_pollution_data_pipeline.load_data scheduled__2024-06-05T00:00:00+00:00 [queued]>
[2024-06-14T11:38:18.984+0000] {taskinstance.py:2306} INFO - Starting attempt 2 of 6
[2024-06-14T11:38:19.049+0000] {taskinstance.py:2330} INFO - Executing <Task(_PythonDecoratedOperator): load_data> on 2024-06-05 00:00:00+00:00
[2024-06-14T11:38:19.084+0000] {standard_task_runner.py:63} INFO - Started process 366 to run task
[2024-06-14T11:38:19.138+0000] {standard_task_runner.py:90} INFO - Running: ['***', 'tasks', 'run', 'Air_pollution_data_pipeline', 'load_data', 'scheduled__2024-06-05T00:00:00+00:00', '--job-id', '27', '--raw', '--subdir', 'DAGS_FOLDER/main.py', '--cfg-path', '/tmp/tmp40leh0rd']
[2024-06-14T11:38:19.180+0000] {standard_task_runner.py:91} INFO - Job 27: Subtask load_data
[2024-06-14T11:38:19.647+0000] {task_command.py:426} INFO - Running <TaskInstance: Air_pollution_data_pipeline.load_data scheduled__2024-06-05T00:00:00+00:00 [running]> on host 077b299c21d5
[2024-06-14T11:38:20.411+0000] {taskinstance.py:2648} INFO - Exporting env vars: AIRFLOW_CTX_DAG_OWNER='khalid' AIRFLOW_CTX_DAG_ID='Air_pollution_data_pipeline' AIRFLOW_CTX_TASK_ID='load_data' AIRFLOW_CTX_EXECUTION_DATE='2024-06-05T00:00:00+00:00' AIRFLOW_CTX_TRY_NUMBER='2' AIRFLOW_CTX_DAG_RUN_ID='scheduled__2024-06-05T00:00:00+00:00'
[2024-06-14T11:38:20.430+0000] {taskinstance.py:430} INFO - ::endgroup::
[2024-06-14T11:38:20.442+0000] {data_load.py:11} INFO - starting data extration from source
[2024-06-14T11:38:22.825+0000] {data_load.py:20} ERROR - error loading data to local drive
[2024-06-14T11:38:22.827+0000] {taskinstance.py:441} INFO - ::group::Post task execution logs
[2024-06-14T11:38:22.829+0000] {taskinstance.py:2905} ERROR - Task failed with exception
Traceback (most recent call last):
  File "/home/airflow/.local/lib/python3.10/site-packages/airflow/models/taskinstance.py", line 465, in _execute_task
    result = _execute_callable(context=context, **execute_callable_kwargs)
  File "/home/airflow/.local/lib/python3.10/site-packages/airflow/models/taskinstance.py", line 432, in _execute_callable
    return execute_callable(context=context, **execute_callable_kwargs)
  File "/home/airflow/.local/lib/python3.10/site-packages/airflow/models/baseoperator.py", line 401, in wrapper
    return func(self, *args, **kwargs)
  File "/home/airflow/.local/lib/python3.10/site-packages/airflow/decorators/base.py", line 265, in execute
    return_value = super().execute(context)
  File "/home/airflow/.local/lib/python3.10/site-packages/airflow/models/baseoperator.py", line 401, in wrapper
    return func(self, *args, **kwargs)
  File "/home/airflow/.local/lib/python3.10/site-packages/airflow/operators/python.py", line 235, in execute
    return_value = self.execute_callable()
  File "/home/airflow/.local/lib/python3.10/site-packages/airflow/operators/python.py", line 252, in execute_callable
    return self.python_callable(*self.op_args, **self.op_kwargs)
  File "/opt/airflow/dags/dataload/data_load.py", line 14, in load_data
    datadf.to_csv(f'{save_path}/emission_data.csv', index= False)
  File "/home/airflow/.local/lib/python3.10/site-packages/pandas/util/_decorators.py", line 333, in wrapper
    return func(*args, **kwargs)
  File "/home/airflow/.local/lib/python3.10/site-packages/pandas/core/generic.py", line 3967, in to_csv
    return DataFrameRenderer(formatter).to_csv(
  File "/home/airflow/.local/lib/python3.10/site-packages/pandas/io/formats/format.py", line 1014, in to_csv
    csv_formatter.save()
  File "/home/airflow/.local/lib/python3.10/site-packages/pandas/io/formats/csvs.py", line 251, in save
    with get_handle(
  File "/home/airflow/.local/lib/python3.10/site-packages/pandas/io/common.py", line 873, in get_handle
    handle = open(
PermissionError: [Errno 13] Permission denied: '/opt/airflow/save/emission_data.csv'
[2024-06-14T11:38:22.866+0000] {taskinstance.py:1206} INFO - Marking task as UP_FOR_RETRY. dag_id=Air_pollution_data_pipeline, task_id=load_data, run_id=scheduled__2024-06-05T00:00:00+00:00, execution_date=20240605T000000, start_date=20240614T113818, end_date=20240614T113822
[2024-06-14T11:38:23.044+0000] {standard_task_runner.py:110} ERROR - Failed to execute job 27 for task load_data ([Errno 13] Permission denied: '/opt/airflow/save/emission_data.csv'; 366)
[2024-06-14T11:38:23.096+0000] {local_task_job_runner.py:240} INFO - Task exited with return code 1
[2024-06-14T11:38:23.317+0000] {taskinstance.py:3503} INFO - 0 downstream tasks scheduled from follow-on schedule check
[2024-06-14T11:38:23.333+0000] {local_task_job_runner.py:222} INFO - ::endgroup::
