[2024-06-13T23:14:01.483+0000] {local_task_job_runner.py:120} INFO - ::group::Pre task execution logs
[2024-06-13T23:14:01.939+0000] {taskinstance.py:2076} INFO - Dependencies all met for dep_context=non-requeueable deps ti=<TaskInstance: Air_pollution_data_pipeline.load_data scheduled__2024-05-31T00:00:00+00:00 [queued]>
[2024-06-13T23:14:02.002+0000] {taskinstance.py:2076} INFO - Dependencies all met for dep_context=requeueable deps ti=<TaskInstance: Air_pollution_data_pipeline.load_data scheduled__2024-05-31T00:00:00+00:00 [queued]>
[2024-06-13T23:14:02.004+0000] {taskinstance.py:2306} INFO - Starting attempt 2 of 6
[2024-06-13T23:14:02.197+0000] {taskinstance.py:2330} INFO - Executing <Task(_PythonDecoratedOperator): load_data> on 2024-05-31 00:00:00+00:00
[2024-06-13T23:14:02.257+0000] {standard_task_runner.py:63} INFO - Started process 455 to run task
[2024-06-13T23:14:02.371+0000] {standard_task_runner.py:90} INFO - Running: ['***', 'tasks', 'run', 'Air_pollution_data_pipeline', 'load_data', 'scheduled__2024-05-31T00:00:00+00:00', '--job-id', '17', '--raw', '--subdir', 'DAGS_FOLDER/main.py', '--cfg-path', '/tmp/tmpjojtjhxd']
[2024-06-13T23:14:02.436+0000] {standard_task_runner.py:91} INFO - Job 17: Subtask load_data
[2024-06-13T23:14:03.375+0000] {task_command.py:426} INFO - Running <TaskInstance: Air_pollution_data_pipeline.load_data scheduled__2024-05-31T00:00:00+00:00 [running]> on host 1ebbf628611f
[2024-06-13T23:14:03.935+0000] {taskinstance.py:2648} INFO - Exporting env vars: AIRFLOW_CTX_DAG_OWNER='khalid' AIRFLOW_CTX_DAG_ID='Air_pollution_data_pipeline' AIRFLOW_CTX_TASK_ID='load_data' AIRFLOW_CTX_EXECUTION_DATE='2024-05-31T00:00:00+00:00' AIRFLOW_CTX_TRY_NUMBER='2' AIRFLOW_CTX_DAG_RUN_ID='scheduled__2024-05-31T00:00:00+00:00'
[2024-06-13T23:14:03.938+0000] {taskinstance.py:430} INFO - ::endgroup::
[2024-06-13T23:14:03.942+0000] {data_load.py:11} INFO - starting data extration from source
[2024-06-13T23:14:06.919+0000] {data_load.py:20} ERROR - error loading data to local drive
[2024-06-13T23:14:06.920+0000] {taskinstance.py:441} INFO - ::group::Post task execution logs
[2024-06-13T23:14:06.921+0000] {taskinstance.py:2905} ERROR - Task failed with exception
Traceback (most recent call last):
  File "/home/airflow/.local/lib/python3.10/site-packages/airflow/models/taskinstance.py", line 465, in _execute_task
    result = _execute_callable(context=context, **execute_callable_kwargs)
  File "/home/airflow/.local/lib/python3.10/site-packages/airflow/models/taskinstance.py", line 432, in _execute_callable
    return execute_callable(context=context, **execute_callable_kwargs)
  File "/home/airflow/.local/lib/python3.10/site-packages/airflow/models/baseoperator.py", line 401, in wrapper
    return func(self, *args, **kwargs)
  File "/home/airflow/.local/lib/python3.10/site-packages/airflow/decorators/base.py", line 265, in execute
    return_value = super().execute(context)
  File "/home/airflow/.local/lib/python3.10/site-packages/airflow/models/baseoperator.py", line 401, in wrapper
    return func(self, *args, **kwargs)
  File "/home/airflow/.local/lib/python3.10/site-packages/airflow/operators/python.py", line 235, in execute
    return_value = self.execute_callable()
  File "/home/airflow/.local/lib/python3.10/site-packages/airflow/operators/python.py", line 252, in execute_callable
    return self.python_callable(*self.op_args, **self.op_kwargs)
  File "/opt/airflow/dags/dataload/data_load.py", line 14, in load_data
    datadf.to_csv(f'{save_path}/emission_data.csv', index= False)
  File "/home/airflow/.local/lib/python3.10/site-packages/pandas/util/_decorators.py", line 333, in wrapper
    return func(*args, **kwargs)
  File "/home/airflow/.local/lib/python3.10/site-packages/pandas/core/generic.py", line 3967, in to_csv
    return DataFrameRenderer(formatter).to_csv(
  File "/home/airflow/.local/lib/python3.10/site-packages/pandas/io/formats/format.py", line 1014, in to_csv
    csv_formatter.save()
  File "/home/airflow/.local/lib/python3.10/site-packages/pandas/io/formats/csvs.py", line 251, in save
    with get_handle(
  File "/home/airflow/.local/lib/python3.10/site-packages/pandas/io/common.py", line 873, in get_handle
    handle = open(
PermissionError: [Errno 13] Permission denied: '/opt/airflow/save/emission_data.csv'
[2024-06-13T23:14:06.992+0000] {taskinstance.py:1206} INFO - Marking task as UP_FOR_RETRY. dag_id=Air_pollution_data_pipeline, task_id=load_data, run_id=scheduled__2024-05-31T00:00:00+00:00, execution_date=20240531T000000, start_date=20240613T231401, end_date=20240613T231406
[2024-06-13T23:14:07.051+0000] {standard_task_runner.py:110} ERROR - Failed to execute job 17 for task load_data ([Errno 13] Permission denied: '/opt/airflow/save/emission_data.csv'; 455)
[2024-06-13T23:14:07.119+0000] {local_task_job_runner.py:240} INFO - Task exited with return code 1
[2024-06-13T23:14:07.217+0000] {taskinstance.py:3503} INFO - 0 downstream tasks scheduled from follow-on schedule check
[2024-06-13T23:14:07.229+0000] {local_task_job_runner.py:222} INFO - ::endgroup::
[2024-06-14T09:54:14.119+0000] {local_task_job_runner.py:120} INFO - ::group::Pre task execution logs
[2024-06-14T09:54:15.560+0000] {taskinstance.py:2076} INFO - Dependencies all met for dep_context=non-requeueable deps ti=<TaskInstance: Air_pollution_data_pipeline.load_data scheduled__2024-05-31T00:00:00+00:00 [queued]>
[2024-06-14T09:54:15.606+0000] {taskinstance.py:2076} INFO - Dependencies all met for dep_context=requeueable deps ti=<TaskInstance: Air_pollution_data_pipeline.load_data scheduled__2024-05-31T00:00:00+00:00 [queued]>
[2024-06-14T09:54:15.634+0000] {taskinstance.py:2306} INFO - Starting attempt 2 of 6
[2024-06-14T09:54:17.299+0000] {taskinstance.py:2330} INFO - Executing <Task(_PythonDecoratedOperator): load_data> on 2024-05-31 00:00:00+00:00
[2024-06-14T09:54:17.449+0000] {standard_task_runner.py:63} INFO - Started process 349 to run task
[2024-06-14T09:54:17.953+0000] {standard_task_runner.py:90} INFO - Running: ['***', 'tasks', 'run', 'Air_pollution_data_pipeline', 'load_data', 'scheduled__2024-05-31T00:00:00+00:00', '--job-id', '23', '--raw', '--subdir', 'DAGS_FOLDER/main.py', '--cfg-path', '/tmp/tmpmo_d0nik']
[2024-06-14T09:54:18.057+0000] {standard_task_runner.py:91} INFO - Job 23: Subtask load_data
[2024-06-14T09:54:20.373+0000] {task_command.py:426} INFO - Running <TaskInstance: Air_pollution_data_pipeline.load_data scheduled__2024-05-31T00:00:00+00:00 [running]> on host 38d417aa145d
[2024-06-14T09:54:22.618+0000] {taskinstance.py:2648} INFO - Exporting env vars: AIRFLOW_CTX_DAG_OWNER='khalid' AIRFLOW_CTX_DAG_ID='Air_pollution_data_pipeline' AIRFLOW_CTX_TASK_ID='load_data' AIRFLOW_CTX_EXECUTION_DATE='2024-05-31T00:00:00+00:00' AIRFLOW_CTX_TRY_NUMBER='2' AIRFLOW_CTX_DAG_RUN_ID='scheduled__2024-05-31T00:00:00+00:00'
[2024-06-14T09:54:22.648+0000] {taskinstance.py:430} INFO - ::endgroup::
[2024-06-14T09:54:22.650+0000] {data_load.py:11} INFO - starting data extration from source
[2024-06-14T09:54:25.403+0000] {data_load.py:20} ERROR - error loading data to local drive
[2024-06-14T09:54:25.405+0000] {taskinstance.py:441} INFO - ::group::Post task execution logs
[2024-06-14T09:54:25.406+0000] {taskinstance.py:2905} ERROR - Task failed with exception
Traceback (most recent call last):
  File "/home/airflow/.local/lib/python3.10/site-packages/airflow/models/taskinstance.py", line 465, in _execute_task
    result = _execute_callable(context=context, **execute_callable_kwargs)
  File "/home/airflow/.local/lib/python3.10/site-packages/airflow/models/taskinstance.py", line 432, in _execute_callable
    return execute_callable(context=context, **execute_callable_kwargs)
  File "/home/airflow/.local/lib/python3.10/site-packages/airflow/models/baseoperator.py", line 401, in wrapper
    return func(self, *args, **kwargs)
  File "/home/airflow/.local/lib/python3.10/site-packages/airflow/decorators/base.py", line 265, in execute
    return_value = super().execute(context)
  File "/home/airflow/.local/lib/python3.10/site-packages/airflow/models/baseoperator.py", line 401, in wrapper
    return func(self, *args, **kwargs)
  File "/home/airflow/.local/lib/python3.10/site-packages/airflow/operators/python.py", line 235, in execute
    return_value = self.execute_callable()
  File "/home/airflow/.local/lib/python3.10/site-packages/airflow/operators/python.py", line 252, in execute_callable
    return self.python_callable(*self.op_args, **self.op_kwargs)
  File "/opt/airflow/dags/dataload/data_load.py", line 14, in load_data
    datadf.to_csv(f'{save_path}/emission_data.csv', index= False)
  File "/home/airflow/.local/lib/python3.10/site-packages/pandas/util/_decorators.py", line 333, in wrapper
    return func(*args, **kwargs)
  File "/home/airflow/.local/lib/python3.10/site-packages/pandas/core/generic.py", line 3967, in to_csv
    return DataFrameRenderer(formatter).to_csv(
  File "/home/airflow/.local/lib/python3.10/site-packages/pandas/io/formats/format.py", line 1014, in to_csv
    csv_formatter.save()
  File "/home/airflow/.local/lib/python3.10/site-packages/pandas/io/formats/csvs.py", line 251, in save
    with get_handle(
  File "/home/airflow/.local/lib/python3.10/site-packages/pandas/io/common.py", line 873, in get_handle
    handle = open(
PermissionError: [Errno 13] Permission denied: '/opt/airflow/save/emission_data.csv'
[2024-06-14T09:54:25.466+0000] {taskinstance.py:1206} INFO - Marking task as UP_FOR_RETRY. dag_id=Air_pollution_data_pipeline, task_id=load_data, run_id=scheduled__2024-05-31T00:00:00+00:00, execution_date=20240531T000000, start_date=20240614T095415, end_date=20240614T095425
[2024-06-14T09:54:25.615+0000] {standard_task_runner.py:110} ERROR - Failed to execute job 23 for task load_data ([Errno 13] Permission denied: '/opt/airflow/save/emission_data.csv'; 349)
[2024-06-14T09:54:25.747+0000] {local_task_job_runner.py:240} INFO - Task exited with return code 1
[2024-06-14T09:54:26.437+0000] {taskinstance.py:3503} INFO - 0 downstream tasks scheduled from follow-on schedule check
[2024-06-14T09:54:26.486+0000] {local_task_job_runner.py:222} INFO - ::endgroup::
[2024-06-14T10:04:22.306+0000] {local_task_job_runner.py:120} INFO - ::group::Pre task execution logs
[2024-06-14T10:04:22.381+0000] {taskinstance.py:2076} INFO - Dependencies all met for dep_context=non-requeueable deps ti=<TaskInstance: Air_pollution_data_pipeline.load_data scheduled__2024-05-31T00:00:00+00:00 [queued]>
[2024-06-14T10:04:22.405+0000] {taskinstance.py:2076} INFO - Dependencies all met for dep_context=requeueable deps ti=<TaskInstance: Air_pollution_data_pipeline.load_data scheduled__2024-05-31T00:00:00+00:00 [queued]>
[2024-06-14T10:04:22.406+0000] {taskinstance.py:2306} INFO - Starting attempt 2 of 6
[2024-06-14T10:04:22.442+0000] {taskinstance.py:2330} INFO - Executing <Task(_PythonDecoratedOperator): load_data> on 2024-05-31 00:00:00+00:00
[2024-06-14T10:04:22.453+0000] {standard_task_runner.py:63} INFO - Started process 321 to run task
[2024-06-14T10:04:22.480+0000] {standard_task_runner.py:90} INFO - Running: ['***', 'tasks', 'run', 'Air_pollution_data_pipeline', 'load_data', 'scheduled__2024-05-31T00:00:00+00:00', '--job-id', '19', '--raw', '--subdir', 'DAGS_FOLDER/main.py', '--cfg-path', '/tmp/tmpr79p8cxn']
[2024-06-14T10:04:22.492+0000] {standard_task_runner.py:91} INFO - Job 19: Subtask load_data
[2024-06-14T10:04:22.652+0000] {task_command.py:426} INFO - Running <TaskInstance: Air_pollution_data_pipeline.load_data scheduled__2024-05-31T00:00:00+00:00 [running]> on host aad58c289bbe
[2024-06-14T10:04:22.861+0000] {taskinstance.py:2648} INFO - Exporting env vars: AIRFLOW_CTX_DAG_OWNER='khalid' AIRFLOW_CTX_DAG_ID='Air_pollution_data_pipeline' AIRFLOW_CTX_TASK_ID='load_data' AIRFLOW_CTX_EXECUTION_DATE='2024-05-31T00:00:00+00:00' AIRFLOW_CTX_TRY_NUMBER='2' AIRFLOW_CTX_DAG_RUN_ID='scheduled__2024-05-31T00:00:00+00:00'
[2024-06-14T10:04:22.863+0000] {taskinstance.py:430} INFO - ::endgroup::
[2024-06-14T10:04:22.865+0000] {data_load.py:11} INFO - starting data extration from source
[2024-06-14T10:04:25.130+0000] {data_load.py:20} ERROR - error loading data to local drive
[2024-06-14T10:04:25.131+0000] {taskinstance.py:441} INFO - ::group::Post task execution logs
[2024-06-14T10:04:25.133+0000] {taskinstance.py:2905} ERROR - Task failed with exception
Traceback (most recent call last):
  File "/home/airflow/.local/lib/python3.10/site-packages/airflow/models/taskinstance.py", line 465, in _execute_task
    result = _execute_callable(context=context, **execute_callable_kwargs)
  File "/home/airflow/.local/lib/python3.10/site-packages/airflow/models/taskinstance.py", line 432, in _execute_callable
    return execute_callable(context=context, **execute_callable_kwargs)
  File "/home/airflow/.local/lib/python3.10/site-packages/airflow/models/baseoperator.py", line 401, in wrapper
    return func(self, *args, **kwargs)
  File "/home/airflow/.local/lib/python3.10/site-packages/airflow/decorators/base.py", line 265, in execute
    return_value = super().execute(context)
  File "/home/airflow/.local/lib/python3.10/site-packages/airflow/models/baseoperator.py", line 401, in wrapper
    return func(self, *args, **kwargs)
  File "/home/airflow/.local/lib/python3.10/site-packages/airflow/operators/python.py", line 235, in execute
    return_value = self.execute_callable()
  File "/home/airflow/.local/lib/python3.10/site-packages/airflow/operators/python.py", line 252, in execute_callable
    return self.python_callable(*self.op_args, **self.op_kwargs)
  File "/opt/airflow/dags/dataload/data_load.py", line 14, in load_data
    datadf.to_csv(f'{save_path}/emission_data.csv', index= False)
  File "/home/airflow/.local/lib/python3.10/site-packages/pandas/util/_decorators.py", line 333, in wrapper
    return func(*args, **kwargs)
  File "/home/airflow/.local/lib/python3.10/site-packages/pandas/core/generic.py", line 3967, in to_csv
    return DataFrameRenderer(formatter).to_csv(
  File "/home/airflow/.local/lib/python3.10/site-packages/pandas/io/formats/format.py", line 1014, in to_csv
    csv_formatter.save()
  File "/home/airflow/.local/lib/python3.10/site-packages/pandas/io/formats/csvs.py", line 251, in save
    with get_handle(
  File "/home/airflow/.local/lib/python3.10/site-packages/pandas/io/common.py", line 873, in get_handle
    handle = open(
PermissionError: [Errno 13] Permission denied: '/opt/airflow/save/emission_data.csv'
[2024-06-14T10:04:25.174+0000] {taskinstance.py:1206} INFO - Marking task as UP_FOR_RETRY. dag_id=Air_pollution_data_pipeline, task_id=load_data, run_id=scheduled__2024-05-31T00:00:00+00:00, execution_date=20240531T000000, start_date=20240614T100422, end_date=20240614T100425
[2024-06-14T10:04:25.291+0000] {standard_task_runner.py:110} ERROR - Failed to execute job 19 for task load_data ([Errno 13] Permission denied: '/opt/airflow/save/emission_data.csv'; 321)
[2024-06-14T10:04:25.345+0000] {local_task_job_runner.py:240} INFO - Task exited with return code 1
[2024-06-14T10:04:25.438+0000] {taskinstance.py:3503} INFO - 0 downstream tasks scheduled from follow-on schedule check
[2024-06-14T10:04:25.445+0000] {local_task_job_runner.py:222} INFO - ::endgroup::
[2024-06-14T11:38:11.551+0000] {local_task_job_runner.py:120} INFO - ::group::Pre task execution logs
[2024-06-14T11:38:11.724+0000] {taskinstance.py:2076} INFO - Dependencies all met for dep_context=non-requeueable deps ti=<TaskInstance: Air_pollution_data_pipeline.load_data scheduled__2024-05-31T00:00:00+00:00 [queued]>
[2024-06-14T11:38:11.790+0000] {taskinstance.py:2076} INFO - Dependencies all met for dep_context=requeueable deps ti=<TaskInstance: Air_pollution_data_pipeline.load_data scheduled__2024-05-31T00:00:00+00:00 [queued]>
[2024-06-14T11:38:11.793+0000] {taskinstance.py:2306} INFO - Starting attempt 2 of 6
[2024-06-14T11:38:12.071+0000] {taskinstance.py:2330} INFO - Executing <Task(_PythonDecoratedOperator): load_data> on 2024-05-31 00:00:00+00:00
[2024-06-14T11:38:12.112+0000] {standard_task_runner.py:63} INFO - Started process 342 to run task
[2024-06-14T11:38:12.244+0000] {standard_task_runner.py:90} INFO - Running: ['***', 'tasks', 'run', 'Air_pollution_data_pipeline', 'load_data', 'scheduled__2024-05-31T00:00:00+00:00', '--job-id', '19', '--raw', '--subdir', 'DAGS_FOLDER/main.py', '--cfg-path', '/tmp/tmpektg3ltq']
[2024-06-14T11:38:12.270+0000] {standard_task_runner.py:91} INFO - Job 19: Subtask load_data
[2024-06-14T11:38:13.530+0000] {task_command.py:426} INFO - Running <TaskInstance: Air_pollution_data_pipeline.load_data scheduled__2024-05-31T00:00:00+00:00 [running]> on host 077b299c21d5
[2024-06-14T11:38:14.367+0000] {taskinstance.py:2648} INFO - Exporting env vars: AIRFLOW_CTX_DAG_OWNER='khalid' AIRFLOW_CTX_DAG_ID='Air_pollution_data_pipeline' AIRFLOW_CTX_TASK_ID='load_data' AIRFLOW_CTX_EXECUTION_DATE='2024-05-31T00:00:00+00:00' AIRFLOW_CTX_TRY_NUMBER='2' AIRFLOW_CTX_DAG_RUN_ID='scheduled__2024-05-31T00:00:00+00:00'
[2024-06-14T11:38:14.377+0000] {taskinstance.py:430} INFO - ::endgroup::
[2024-06-14T11:38:14.379+0000] {data_load.py:11} INFO - starting data extration from source
[2024-06-14T11:38:17.279+0000] {data_load.py:20} ERROR - error loading data to local drive
[2024-06-14T11:38:17.281+0000] {taskinstance.py:441} INFO - ::group::Post task execution logs
[2024-06-14T11:38:17.282+0000] {taskinstance.py:2905} ERROR - Task failed with exception
Traceback (most recent call last):
  File "/home/airflow/.local/lib/python3.10/site-packages/airflow/models/taskinstance.py", line 465, in _execute_task
    result = _execute_callable(context=context, **execute_callable_kwargs)
  File "/home/airflow/.local/lib/python3.10/site-packages/airflow/models/taskinstance.py", line 432, in _execute_callable
    return execute_callable(context=context, **execute_callable_kwargs)
  File "/home/airflow/.local/lib/python3.10/site-packages/airflow/models/baseoperator.py", line 401, in wrapper
    return func(self, *args, **kwargs)
  File "/home/airflow/.local/lib/python3.10/site-packages/airflow/decorators/base.py", line 265, in execute
    return_value = super().execute(context)
  File "/home/airflow/.local/lib/python3.10/site-packages/airflow/models/baseoperator.py", line 401, in wrapper
    return func(self, *args, **kwargs)
  File "/home/airflow/.local/lib/python3.10/site-packages/airflow/operators/python.py", line 235, in execute
    return_value = self.execute_callable()
  File "/home/airflow/.local/lib/python3.10/site-packages/airflow/operators/python.py", line 252, in execute_callable
    return self.python_callable(*self.op_args, **self.op_kwargs)
  File "/opt/airflow/dags/dataload/data_load.py", line 14, in load_data
    datadf.to_csv(f'{save_path}/emission_data.csv', index= False)
  File "/home/airflow/.local/lib/python3.10/site-packages/pandas/util/_decorators.py", line 333, in wrapper
    return func(*args, **kwargs)
  File "/home/airflow/.local/lib/python3.10/site-packages/pandas/core/generic.py", line 3967, in to_csv
    return DataFrameRenderer(formatter).to_csv(
  File "/home/airflow/.local/lib/python3.10/site-packages/pandas/io/formats/format.py", line 1014, in to_csv
    csv_formatter.save()
  File "/home/airflow/.local/lib/python3.10/site-packages/pandas/io/formats/csvs.py", line 251, in save
    with get_handle(
  File "/home/airflow/.local/lib/python3.10/site-packages/pandas/io/common.py", line 873, in get_handle
    handle = open(
PermissionError: [Errno 13] Permission denied: '/opt/airflow/save/emission_data.csv'
[2024-06-14T11:38:17.354+0000] {taskinstance.py:1206} INFO - Marking task as UP_FOR_RETRY. dag_id=Air_pollution_data_pipeline, task_id=load_data, run_id=scheduled__2024-05-31T00:00:00+00:00, execution_date=20240531T000000, start_date=20240614T113811, end_date=20240614T113817
[2024-06-14T11:38:17.409+0000] {standard_task_runner.py:110} ERROR - Failed to execute job 19 for task load_data ([Errno 13] Permission denied: '/opt/airflow/save/emission_data.csv'; 342)
[2024-06-14T11:38:17.469+0000] {local_task_job_runner.py:240} INFO - Task exited with return code 1
[2024-06-14T11:38:17.588+0000] {local_task_job_runner.py:222} INFO - ::endgroup::
