[2024-06-13T23:16:10.348+0000] {local_task_job_runner.py:120} INFO - ::group::Pre task execution logs
[2024-06-13T23:16:10.423+0000] {taskinstance.py:2076} INFO - Dependencies all met for dep_context=non-requeueable deps ti=<TaskInstance: Air_pollution_data_pipeline.load_data scheduled__2024-05-31T00:00:00+00:00 [queued]>
[2024-06-13T23:16:10.447+0000] {taskinstance.py:2076} INFO - Dependencies all met for dep_context=requeueable deps ti=<TaskInstance: Air_pollution_data_pipeline.load_data scheduled__2024-05-31T00:00:00+00:00 [queued]>
[2024-06-13T23:16:10.448+0000] {taskinstance.py:2306} INFO - Starting attempt 3 of 6
[2024-06-13T23:16:10.728+0000] {taskinstance.py:2330} INFO - Executing <Task(_PythonDecoratedOperator): load_data> on 2024-05-31 00:00:00+00:00
[2024-06-13T23:16:10.738+0000] {standard_task_runner.py:63} INFO - Started process 547 to run task
[2024-06-13T23:16:10.745+0000] {standard_task_runner.py:90} INFO - Running: ['***', 'tasks', 'run', 'Air_pollution_data_pipeline', 'load_data', 'scheduled__2024-05-31T00:00:00+00:00', '--job-id', '31', '--raw', '--subdir', 'DAGS_FOLDER/main.py', '--cfg-path', '/tmp/tmpnupu7uuh']
[2024-06-13T23:16:10.750+0000] {standard_task_runner.py:91} INFO - Job 31: Subtask load_data
[2024-06-13T23:16:10.848+0000] {task_command.py:426} INFO - Running <TaskInstance: Air_pollution_data_pipeline.load_data scheduled__2024-05-31T00:00:00+00:00 [running]> on host 1ebbf628611f
[2024-06-13T23:16:11.066+0000] {taskinstance.py:2648} INFO - Exporting env vars: AIRFLOW_CTX_DAG_OWNER='khalid' AIRFLOW_CTX_DAG_ID='Air_pollution_data_pipeline' AIRFLOW_CTX_TASK_ID='load_data' AIRFLOW_CTX_EXECUTION_DATE='2024-05-31T00:00:00+00:00' AIRFLOW_CTX_TRY_NUMBER='3' AIRFLOW_CTX_DAG_RUN_ID='scheduled__2024-05-31T00:00:00+00:00'
[2024-06-13T23:16:11.069+0000] {taskinstance.py:430} INFO - ::endgroup::
[2024-06-13T23:16:11.072+0000] {data_load.py:11} INFO - starting data extration from source
[2024-06-13T23:16:13.731+0000] {data_load.py:20} ERROR - error loading data to local drive
[2024-06-13T23:16:13.738+0000] {taskinstance.py:441} INFO - ::group::Post task execution logs
[2024-06-13T23:16:13.739+0000] {taskinstance.py:2905} ERROR - Task failed with exception
Traceback (most recent call last):
  File "/home/airflow/.local/lib/python3.10/site-packages/airflow/models/taskinstance.py", line 465, in _execute_task
    result = _execute_callable(context=context, **execute_callable_kwargs)
  File "/home/airflow/.local/lib/python3.10/site-packages/airflow/models/taskinstance.py", line 432, in _execute_callable
    return execute_callable(context=context, **execute_callable_kwargs)
  File "/home/airflow/.local/lib/python3.10/site-packages/airflow/models/baseoperator.py", line 401, in wrapper
    return func(self, *args, **kwargs)
  File "/home/airflow/.local/lib/python3.10/site-packages/airflow/decorators/base.py", line 265, in execute
    return_value = super().execute(context)
  File "/home/airflow/.local/lib/python3.10/site-packages/airflow/models/baseoperator.py", line 401, in wrapper
    return func(self, *args, **kwargs)
  File "/home/airflow/.local/lib/python3.10/site-packages/airflow/operators/python.py", line 235, in execute
    return_value = self.execute_callable()
  File "/home/airflow/.local/lib/python3.10/site-packages/airflow/operators/python.py", line 252, in execute_callable
    return self.python_callable(*self.op_args, **self.op_kwargs)
  File "/opt/airflow/dags/dataload/data_load.py", line 14, in load_data
    datadf.to_csv(f'{save_path}/emission_data.csv', index= False)
  File "/home/airflow/.local/lib/python3.10/site-packages/pandas/util/_decorators.py", line 333, in wrapper
    return func(*args, **kwargs)
  File "/home/airflow/.local/lib/python3.10/site-packages/pandas/core/generic.py", line 3967, in to_csv
    return DataFrameRenderer(formatter).to_csv(
  File "/home/airflow/.local/lib/python3.10/site-packages/pandas/io/formats/format.py", line 1014, in to_csv
    csv_formatter.save()
  File "/home/airflow/.local/lib/python3.10/site-packages/pandas/io/formats/csvs.py", line 251, in save
    with get_handle(
  File "/home/airflow/.local/lib/python3.10/site-packages/pandas/io/common.py", line 873, in get_handle
    handle = open(
PermissionError: [Errno 13] Permission denied: '/opt/airflow/save/emission_data.csv'
[2024-06-13T23:16:13.794+0000] {taskinstance.py:1206} INFO - Marking task as UP_FOR_RETRY. dag_id=Air_pollution_data_pipeline, task_id=load_data, run_id=scheduled__2024-05-31T00:00:00+00:00, execution_date=20240531T000000, start_date=20240613T231610, end_date=20240613T231613
[2024-06-13T23:16:13.842+0000] {standard_task_runner.py:110} ERROR - Failed to execute job 31 for task load_data ([Errno 13] Permission denied: '/opt/airflow/save/emission_data.csv'; 547)
[2024-06-13T23:16:13.874+0000] {local_task_job_runner.py:240} INFO - Task exited with return code 1
[2024-06-13T23:16:13.965+0000] {taskinstance.py:3503} INFO - 0 downstream tasks scheduled from follow-on schedule check
[2024-06-13T23:16:13.980+0000] {local_task_job_runner.py:222} INFO - ::endgroup::
[2024-06-14T09:56:30.266+0000] {local_task_job_runner.py:120} INFO - ::group::Pre task execution logs
[2024-06-14T09:56:30.353+0000] {taskinstance.py:2076} INFO - Dependencies all met for dep_context=non-requeueable deps ti=<TaskInstance: Air_pollution_data_pipeline.load_data scheduled__2024-05-31T00:00:00+00:00 [queued]>
[2024-06-14T09:56:30.374+0000] {taskinstance.py:2076} INFO - Dependencies all met for dep_context=requeueable deps ti=<TaskInstance: Air_pollution_data_pipeline.load_data scheduled__2024-05-31T00:00:00+00:00 [queued]>
[2024-06-14T09:56:30.375+0000] {taskinstance.py:2306} INFO - Starting attempt 3 of 6
[2024-06-14T09:56:30.413+0000] {taskinstance.py:2330} INFO - Executing <Task(_PythonDecoratedOperator): load_data> on 2024-05-31 00:00:00+00:00
[2024-06-14T09:56:30.431+0000] {standard_task_runner.py:63} INFO - Started process 423 to run task
[2024-06-14T09:56:30.439+0000] {standard_task_runner.py:90} INFO - Running: ['***', 'tasks', 'run', 'Air_pollution_data_pipeline', 'load_data', 'scheduled__2024-05-31T00:00:00+00:00', '--job-id', '38', '--raw', '--subdir', 'DAGS_FOLDER/main.py', '--cfg-path', '/tmp/tmp9d76p_bh']
[2024-06-14T09:56:30.444+0000] {standard_task_runner.py:91} INFO - Job 38: Subtask load_data
[2024-06-14T09:56:30.662+0000] {task_command.py:426} INFO - Running <TaskInstance: Air_pollution_data_pipeline.load_data scheduled__2024-05-31T00:00:00+00:00 [running]> on host 38d417aa145d
[2024-06-14T09:56:30.870+0000] {taskinstance.py:2648} INFO - Exporting env vars: AIRFLOW_CTX_DAG_OWNER='khalid' AIRFLOW_CTX_DAG_ID='Air_pollution_data_pipeline' AIRFLOW_CTX_TASK_ID='load_data' AIRFLOW_CTX_EXECUTION_DATE='2024-05-31T00:00:00+00:00' AIRFLOW_CTX_TRY_NUMBER='3' AIRFLOW_CTX_DAG_RUN_ID='scheduled__2024-05-31T00:00:00+00:00'
[2024-06-14T09:56:30.873+0000] {taskinstance.py:430} INFO - ::endgroup::
[2024-06-14T09:56:30.875+0000] {data_load.py:11} INFO - starting data extration from source
[2024-06-14T09:56:33.558+0000] {data_load.py:20} ERROR - error loading data to local drive
[2024-06-14T09:56:33.562+0000] {taskinstance.py:441} INFO - ::group::Post task execution logs
[2024-06-14T09:56:33.572+0000] {taskinstance.py:2905} ERROR - Task failed with exception
Traceback (most recent call last):
  File "/home/airflow/.local/lib/python3.10/site-packages/airflow/models/taskinstance.py", line 465, in _execute_task
    result = _execute_callable(context=context, **execute_callable_kwargs)
  File "/home/airflow/.local/lib/python3.10/site-packages/airflow/models/taskinstance.py", line 432, in _execute_callable
    return execute_callable(context=context, **execute_callable_kwargs)
  File "/home/airflow/.local/lib/python3.10/site-packages/airflow/models/baseoperator.py", line 401, in wrapper
    return func(self, *args, **kwargs)
  File "/home/airflow/.local/lib/python3.10/site-packages/airflow/decorators/base.py", line 265, in execute
    return_value = super().execute(context)
  File "/home/airflow/.local/lib/python3.10/site-packages/airflow/models/baseoperator.py", line 401, in wrapper
    return func(self, *args, **kwargs)
  File "/home/airflow/.local/lib/python3.10/site-packages/airflow/operators/python.py", line 235, in execute
    return_value = self.execute_callable()
  File "/home/airflow/.local/lib/python3.10/site-packages/airflow/operators/python.py", line 252, in execute_callable
    return self.python_callable(*self.op_args, **self.op_kwargs)
  File "/opt/airflow/dags/dataload/data_load.py", line 14, in load_data
    datadf.to_csv(f'{save_path}/emission_data.csv', index= False)
  File "/home/airflow/.local/lib/python3.10/site-packages/pandas/util/_decorators.py", line 333, in wrapper
    return func(*args, **kwargs)
  File "/home/airflow/.local/lib/python3.10/site-packages/pandas/core/generic.py", line 3967, in to_csv
    return DataFrameRenderer(formatter).to_csv(
  File "/home/airflow/.local/lib/python3.10/site-packages/pandas/io/formats/format.py", line 1014, in to_csv
    csv_formatter.save()
  File "/home/airflow/.local/lib/python3.10/site-packages/pandas/io/formats/csvs.py", line 251, in save
    with get_handle(
  File "/home/airflow/.local/lib/python3.10/site-packages/pandas/io/common.py", line 873, in get_handle
    handle = open(
PermissionError: [Errno 13] Permission denied: '/opt/airflow/save/emission_data.csv'
[2024-06-14T09:56:33.606+0000] {taskinstance.py:1206} INFO - Marking task as UP_FOR_RETRY. dag_id=Air_pollution_data_pipeline, task_id=load_data, run_id=scheduled__2024-05-31T00:00:00+00:00, execution_date=20240531T000000, start_date=20240614T095630, end_date=20240614T095633
[2024-06-14T09:56:33.656+0000] {standard_task_runner.py:110} ERROR - Failed to execute job 38 for task load_data ([Errno 13] Permission denied: '/opt/airflow/save/emission_data.csv'; 423)
[2024-06-14T09:56:33.702+0000] {local_task_job_runner.py:240} INFO - Task exited with return code 1
[2024-06-14T09:56:33.791+0000] {taskinstance.py:3503} INFO - 0 downstream tasks scheduled from follow-on schedule check
[2024-06-14T09:56:33.798+0000] {local_task_job_runner.py:222} INFO - ::endgroup::
[2024-06-14T10:06:30.479+0000] {local_task_job_runner.py:120} INFO - ::group::Pre task execution logs
[2024-06-14T10:06:30.749+0000] {taskinstance.py:2076} INFO - Dependencies all met for dep_context=non-requeueable deps ti=<TaskInstance: Air_pollution_data_pipeline.load_data scheduled__2024-05-31T00:00:00+00:00 [queued]>
[2024-06-14T10:06:30.782+0000] {taskinstance.py:2076} INFO - Dependencies all met for dep_context=requeueable deps ti=<TaskInstance: Air_pollution_data_pipeline.load_data scheduled__2024-05-31T00:00:00+00:00 [queued]>
[2024-06-14T10:06:30.783+0000] {taskinstance.py:2306} INFO - Starting attempt 3 of 6
[2024-06-14T10:06:30.849+0000] {taskinstance.py:2330} INFO - Executing <Task(_PythonDecoratedOperator): load_data> on 2024-05-31 00:00:00+00:00
[2024-06-14T10:06:30.862+0000] {standard_task_runner.py:63} INFO - Started process 418 to run task
[2024-06-14T10:06:30.897+0000] {standard_task_runner.py:90} INFO - Running: ['***', 'tasks', 'run', 'Air_pollution_data_pipeline', 'load_data', 'scheduled__2024-05-31T00:00:00+00:00', '--job-id', '36', '--raw', '--subdir', 'DAGS_FOLDER/main.py', '--cfg-path', '/tmp/tmpsghh9ycn']
[2024-06-14T10:06:30.904+0000] {standard_task_runner.py:91} INFO - Job 36: Subtask load_data
[2024-06-14T10:06:31.127+0000] {task_command.py:426} INFO - Running <TaskInstance: Air_pollution_data_pipeline.load_data scheduled__2024-05-31T00:00:00+00:00 [running]> on host aad58c289bbe
[2024-06-14T10:06:31.568+0000] {taskinstance.py:2648} INFO - Exporting env vars: AIRFLOW_CTX_DAG_OWNER='khalid' AIRFLOW_CTX_DAG_ID='Air_pollution_data_pipeline' AIRFLOW_CTX_TASK_ID='load_data' AIRFLOW_CTX_EXECUTION_DATE='2024-05-31T00:00:00+00:00' AIRFLOW_CTX_TRY_NUMBER='3' AIRFLOW_CTX_DAG_RUN_ID='scheduled__2024-05-31T00:00:00+00:00'
[2024-06-14T10:06:31.571+0000] {taskinstance.py:430} INFO - ::endgroup::
[2024-06-14T10:06:31.573+0000] {data_load.py:11} INFO - starting data extration from source
[2024-06-14T10:06:35.647+0000] {data_load.py:20} ERROR - error loading data to local drive
[2024-06-14T10:06:35.661+0000] {taskinstance.py:441} INFO - ::group::Post task execution logs
[2024-06-14T10:06:35.663+0000] {taskinstance.py:2905} ERROR - Task failed with exception
Traceback (most recent call last):
  File "/home/airflow/.local/lib/python3.10/site-packages/airflow/models/taskinstance.py", line 465, in _execute_task
    result = _execute_callable(context=context, **execute_callable_kwargs)
  File "/home/airflow/.local/lib/python3.10/site-packages/airflow/models/taskinstance.py", line 432, in _execute_callable
    return execute_callable(context=context, **execute_callable_kwargs)
  File "/home/airflow/.local/lib/python3.10/site-packages/airflow/models/baseoperator.py", line 401, in wrapper
    return func(self, *args, **kwargs)
  File "/home/airflow/.local/lib/python3.10/site-packages/airflow/decorators/base.py", line 265, in execute
    return_value = super().execute(context)
  File "/home/airflow/.local/lib/python3.10/site-packages/airflow/models/baseoperator.py", line 401, in wrapper
    return func(self, *args, **kwargs)
  File "/home/airflow/.local/lib/python3.10/site-packages/airflow/operators/python.py", line 235, in execute
    return_value = self.execute_callable()
  File "/home/airflow/.local/lib/python3.10/site-packages/airflow/operators/python.py", line 252, in execute_callable
    return self.python_callable(*self.op_args, **self.op_kwargs)
  File "/opt/airflow/dags/dataload/data_load.py", line 14, in load_data
    datadf.to_csv(f'{save_path}/emission_data.csv', index= False)
  File "/home/airflow/.local/lib/python3.10/site-packages/pandas/util/_decorators.py", line 333, in wrapper
    return func(*args, **kwargs)
  File "/home/airflow/.local/lib/python3.10/site-packages/pandas/core/generic.py", line 3967, in to_csv
    return DataFrameRenderer(formatter).to_csv(
  File "/home/airflow/.local/lib/python3.10/site-packages/pandas/io/formats/format.py", line 1014, in to_csv
    csv_formatter.save()
  File "/home/airflow/.local/lib/python3.10/site-packages/pandas/io/formats/csvs.py", line 251, in save
    with get_handle(
  File "/home/airflow/.local/lib/python3.10/site-packages/pandas/io/common.py", line 873, in get_handle
    handle = open(
PermissionError: [Errno 13] Permission denied: '/opt/airflow/save/emission_data.csv'
[2024-06-14T10:06:35.898+0000] {taskinstance.py:1206} INFO - Marking task as UP_FOR_RETRY. dag_id=Air_pollution_data_pipeline, task_id=load_data, run_id=scheduled__2024-05-31T00:00:00+00:00, execution_date=20240531T000000, start_date=20240614T100630, end_date=20240614T100635
[2024-06-14T10:06:36.058+0000] {standard_task_runner.py:110} ERROR - Failed to execute job 36 for task load_data ([Errno 13] Permission denied: '/opt/airflow/save/emission_data.csv'; 418)
[2024-06-14T10:06:36.156+0000] {local_task_job_runner.py:240} INFO - Task exited with return code 1
[2024-06-14T10:06:36.202+0000] {local_task_job_runner.py:222} INFO - ::endgroup::
[2024-06-14T11:40:19.311+0000] {local_task_job_runner.py:120} INFO - ::group::Pre task execution logs
[2024-06-14T11:40:19.369+0000] {taskinstance.py:2076} INFO - Dependencies all met for dep_context=non-requeueable deps ti=<TaskInstance: Air_pollution_data_pipeline.load_data scheduled__2024-05-31T00:00:00+00:00 [queued]>
[2024-06-14T11:40:19.383+0000] {taskinstance.py:2076} INFO - Dependencies all met for dep_context=requeueable deps ti=<TaskInstance: Air_pollution_data_pipeline.load_data scheduled__2024-05-31T00:00:00+00:00 [queued]>
[2024-06-14T11:40:19.383+0000] {taskinstance.py:2306} INFO - Starting attempt 3 of 6
[2024-06-14T11:40:19.413+0000] {taskinstance.py:2330} INFO - Executing <Task(_PythonDecoratedOperator): load_data> on 2024-05-31 00:00:00+00:00
[2024-06-14T11:40:19.421+0000] {standard_task_runner.py:63} INFO - Started process 426 to run task
[2024-06-14T11:40:19.428+0000] {standard_task_runner.py:90} INFO - Running: ['***', 'tasks', 'run', 'Air_pollution_data_pipeline', 'load_data', 'scheduled__2024-05-31T00:00:00+00:00', '--job-id', '35', '--raw', '--subdir', 'DAGS_FOLDER/main.py', '--cfg-path', '/tmp/tmp7einwf4h']
[2024-06-14T11:40:19.434+0000] {standard_task_runner.py:91} INFO - Job 35: Subtask load_data
[2024-06-14T11:40:19.518+0000] {task_command.py:426} INFO - Running <TaskInstance: Air_pollution_data_pipeline.load_data scheduled__2024-05-31T00:00:00+00:00 [running]> on host 077b299c21d5
[2024-06-14T11:40:19.641+0000] {taskinstance.py:2648} INFO - Exporting env vars: AIRFLOW_CTX_DAG_OWNER='khalid' AIRFLOW_CTX_DAG_ID='Air_pollution_data_pipeline' AIRFLOW_CTX_TASK_ID='load_data' AIRFLOW_CTX_EXECUTION_DATE='2024-05-31T00:00:00+00:00' AIRFLOW_CTX_TRY_NUMBER='3' AIRFLOW_CTX_DAG_RUN_ID='scheduled__2024-05-31T00:00:00+00:00'
[2024-06-14T11:40:19.642+0000] {taskinstance.py:430} INFO - ::endgroup::
[2024-06-14T11:40:19.643+0000] {data_load.py:11} INFO - starting data extration from source
[2024-06-14T11:40:22.308+0000] {data_load.py:20} ERROR - error loading data to local drive
[2024-06-14T11:40:22.309+0000] {taskinstance.py:441} INFO - ::group::Post task execution logs
[2024-06-14T11:40:22.309+0000] {taskinstance.py:2905} ERROR - Task failed with exception
Traceback (most recent call last):
  File "/home/airflow/.local/lib/python3.10/site-packages/airflow/models/taskinstance.py", line 465, in _execute_task
    result = _execute_callable(context=context, **execute_callable_kwargs)
  File "/home/airflow/.local/lib/python3.10/site-packages/airflow/models/taskinstance.py", line 432, in _execute_callable
    return execute_callable(context=context, **execute_callable_kwargs)
  File "/home/airflow/.local/lib/python3.10/site-packages/airflow/models/baseoperator.py", line 401, in wrapper
    return func(self, *args, **kwargs)
  File "/home/airflow/.local/lib/python3.10/site-packages/airflow/decorators/base.py", line 265, in execute
    return_value = super().execute(context)
  File "/home/airflow/.local/lib/python3.10/site-packages/airflow/models/baseoperator.py", line 401, in wrapper
    return func(self, *args, **kwargs)
  File "/home/airflow/.local/lib/python3.10/site-packages/airflow/operators/python.py", line 235, in execute
    return_value = self.execute_callable()
  File "/home/airflow/.local/lib/python3.10/site-packages/airflow/operators/python.py", line 252, in execute_callable
    return self.python_callable(*self.op_args, **self.op_kwargs)
  File "/opt/airflow/dags/dataload/data_load.py", line 14, in load_data
    datadf.to_csv(f'{save_path}/emission_data.csv', index= False)
  File "/home/airflow/.local/lib/python3.10/site-packages/pandas/util/_decorators.py", line 333, in wrapper
    return func(*args, **kwargs)
  File "/home/airflow/.local/lib/python3.10/site-packages/pandas/core/generic.py", line 3967, in to_csv
    return DataFrameRenderer(formatter).to_csv(
  File "/home/airflow/.local/lib/python3.10/site-packages/pandas/io/formats/format.py", line 1014, in to_csv
    csv_formatter.save()
  File "/home/airflow/.local/lib/python3.10/site-packages/pandas/io/formats/csvs.py", line 251, in save
    with get_handle(
  File "/home/airflow/.local/lib/python3.10/site-packages/pandas/io/common.py", line 873, in get_handle
    handle = open(
PermissionError: [Errno 13] Permission denied: '/opt/airflow/save/emission_data.csv'
[2024-06-14T11:40:22.332+0000] {taskinstance.py:1206} INFO - Marking task as UP_FOR_RETRY. dag_id=Air_pollution_data_pipeline, task_id=load_data, run_id=scheduled__2024-05-31T00:00:00+00:00, execution_date=20240531T000000, start_date=20240614T114019, end_date=20240614T114022
[2024-06-14T11:40:22.804+0000] {standard_task_runner.py:110} ERROR - Failed to execute job 35 for task load_data ([Errno 13] Permission denied: '/opt/airflow/save/emission_data.csv'; 426)
[2024-06-14T11:40:22.855+0000] {local_task_job_runner.py:240} INFO - Task exited with return code 1
[2024-06-14T11:40:22.883+0000] {local_task_job_runner.py:222} INFO - ::endgroup::
